Workbook

Sheet Summary
A1: BofA Exhibit 2: Hyperscaler capex is late cycle, measured at a macro level
A2: Sector capex as % of US GDP through each cycle's speculative build phase. Values read exactly from the PDF's vector chart.
A4: Cycle | B4: Start | C4: End | D4: Start value | E4: Peak | F4: Peak year / quarter | G4: Last value | H4: Peak ÷ start | I4: Fall from peak to last | J4: Years start → peak
A5: US railroads (1900 onwards) | B5: =_xlfn.MINIFS(Annual!A2:A60,Annual!B2:B60,"<>") | C5: =_xlfn.MAXIFS(Annual!A2:A60,Annual!B2:B60,"<>") | D5: =INDEX(Annual!B2:B60,MATCH(B5,Annual!A2:A60,0)) | E5: =MAX(Annual!B2:B60) | F5: =INDEX(Annual!A2:A60,MATCH(E5,Annual!B2:B60,0)) | G5: =INDEX(Annual!B2:B60,MATCH(C5,Annual!A2:A60,0)) | H5: =E5/D5 | I5: =G5/E5-1 | J5: =F5-B5
A6: O&G (1970-80s) | B6: =_xlfn.MINIFS(Annual!A2:A60,Annual!C2:C60,"<>") | C6: =_xlfn.MAXIFS(Annual!A2:A60,Annual!C2:C60,"<>") | D6: =INDEX(Annual!C2:C60,MATCH(B6,Annual!A2:A60,0)) | E6: =MAX(Annual!C2:C60) | F6: =INDEX(Annual!A2:A60,MATCH(E6,Annual!C2:C60,0)) | G6: =INDEX(Annual!C2:C60,MATCH(C6,Annual!A2:A60,0)) | H6: =E6/D6 | I6: =G6/E6-1 | J6: =F6-B6
A7: Telecoms (1990s) | B7: =_xlfn.MINIFS(Annual!A2:A60,Annual!D2:D60,"<>") | C7: =_xlfn.MAXIFS(Annual!A2:A60,Annual!D2:D60,"<>") | D7: =INDEX(Annual!D2:D60,MATCH(B7,Annual!A2:A60,0)) | E7: =MAX(Annual!D2:D60) | F7: =INDEX(Annual!A2:A60,MATCH(E7,Annual!D2:D60,0)) | G7: =INDEX(Annual!D2:D60,MATCH(C7,Annual!A2:A60,0)) | H7: =E7/D7 | I7: =G7/E7-1 | J7: =F7-B7
A8: O&G (Shale) | B8: =_xlfn.MINIFS(Annual!A2:A60,Annual!E2:E60,"<>") | C8: =_xlfn.MAXIFS(Annual!A2:A60,Annual!E2:E60,"<>") | D8: =INDEX(Annual!E2:E60,MATCH(B8,Annual!A2:A60,0)) | E8: =MAX(Annual!E2:E60) | F8: =INDEX(Annual!A2:A60,MATCH(E8,Annual!E2:E60,0)) | G8: =INDEX(Annual!E2:E60,MATCH(C8,Annual!A2:A60,0)) | H8: =E8/D8 | I8: =G8/E8-1 | J8: =F8-B8
A9: Hyperscalers | B9: =MIN(Hyperscalers!B2:B18) | C9: =MAX(Hyperscalers!B2:B18) | D9: =INDEX(Hyperscalers!C2:C18,1) | E9: =MAX(Hyperscalers!C2:C18) | F9: =INDEX(Hyperscalers!A2:A18,MATCH(E9,Hyperscalers!C2:C18,0)) | G9: =INDEX(Hyperscalers!C2:C18,ROWS(Hyperscalers!C2:C18)) | H9: =E9/D9 | I9: =G9/E9-1 | J9: =INDEX(Hyperscalers!B2:B18,MATCH(E9,Hyperscalers!C2:C18,0))-B9
A10: Hyperscalers (lease adjusted) | B10: =MIN(Hyperscalers!B2:B18) | C10: =MAX(Hyperscalers!B2:B18) | D10: =INDEX(Hyperscalers!D2:D18,1) | E10: =MAX(Hyperscalers!D2:D18) | F10: =INDEX(Hyperscalers!A2:A18,MATCH(E10,Hyperscalers!D2:D18,0)) | G10: =INDEX(Hyperscalers!D2:D18,ROWS(Hyperscalers!D2:D18)) | H10: =E10/D10 | I10: =G10/E10-1 | J10: =INDEX(Hyperscalers!B2:B18,MATCH(E10,Hyperscalers!D2:D18,0))-B10
A12: Hyperscaler start/end are quarterly chart positions (2021.5 = mid-2021). Annual series: each year's value is drawn from mid-year Y-1 to Q1 of Y; the year column uses Y.

Sheet Summary (first-hand)
A1: Exhibit 2 rebuilt from first-hand data: sector capex as % of US GDP
A2: Same layout as Summary, but every number comes from the primary sources (NBER tables, BEA Fixed Assets and NIPA, SEC filings, SpaceX prospectus) via the First-hand detail and Hyperscalers first-hand sheets - no BofA input.
A4: Cycle | B4: Start | C4: End | D4: Start value | E4: Peak | F4: Peak year / quarter | G4: Last value | H4: Peak ÷ start | I4: Fall from peak to last | J4: Years start → peak | K4: BofA exhibit peak | L4: Peak: first-hand - BofA (pp)
A5: US railroads (1900 onwards) (first-hand) | B5: =_xlfn.MINIFS('Annual (first-hand)'!A2:A60,'Annual (first-hand)'!B2:B60,"<>") | C5: =_xlfn.MAXIFS('Annual (first-hand)'!A2:A60,'Annual (first-hand)'!B2:B60,"<>") | D5: =INDEX('Annual (first-hand)'!B2:B60,MATCH(B5,'Annual (first-hand)'!A2:A60,0)) | E5: =MAX('Annual (first-hand)'!B2:B60) | F5: =INDEX('Annual (first-hand)'!A2:A60,MATCH(E5,'Annual (first-hand)'!B2:B60,0)) | G5: =INDEX('Annual (first-hand)'!B2:B60,MATCH(C5,'Annual (first-hand)'!A2:A60,0)) | H5: =E5/D5 | I5: =G5/E5-1 | J5: =F5-B5 | K5: =Summary!E5 | L5: =E5-K5
A6: O&G (1970-80s) (first-hand) | B6: =_xlfn.MINIFS('Annual (first-hand)'!A2:A60,'Annual (first-hand)'!C2:C60,"<>") | C6: =_xlfn.MAXIFS('Annual (first-hand)'!A2:A60,'Annual (first-hand)'!C2:C60,"<>") | D6: =INDEX('Annual (first-hand)'!C2:C60,MATCH(B6,'Annual (first-hand)'!A2:A60,0)) | E6: =MAX('Annual (first-hand)'!C2:C60) | F6: =INDEX('Annual (first-hand)'!A2:A60,MATCH(E6,'Annual (first-hand)'!C2:C60,0)) | G6: =INDEX('Annual (first-hand)'!C2:C60,MATCH(C6,'Annual (first-hand)'!A2:A60,0)) | H6: =E6/D6 | I6: =G6/E6-1 | J6: =F6-B6 | K6: =Summary!E6 | L6: =E6-K6
A7: Telecoms (1990s) (first-hand) | B7: =_xlfn.MINIFS('Annual (first-hand)'!A2:A60,'Annual (first-hand)'!D2:D60,"<>") | C7: =_xlfn.MAXIFS('Annual (first-hand)'!A2:A60,'Annual (first-hand)'!D2:D60,"<>") | D7: =INDEX('Annual (first-hand)'!D2:D60,MATCH(B7,'Annual (first-hand)'!A2:A60,0)) | E7: =MAX('Annual (first-hand)'!D2:D60) | F7: =INDEX('Annual (first-hand)'!A2:A60,MATCH(E7,'Annual (first-hand)'!D2:D60,0)) | G7: =INDEX('Annual (first-hand)'!D2:D60,MATCH(C7,'Annual (first-hand)'!A2:A60,0)) | H7: =E7/D7 | I7: =G7/E7-1 | J7: =F7-B7 | K7: =Summary!E7 | L7: =E7-K7
A8: O&G (Shale) (first-hand) | B8: =_xlfn.MINIFS('Annual (first-hand)'!A2:A60,'Annual (first-hand)'!E2:E60,"<>") | C8: =_xlfn.MAXIFS('Annual (first-hand)'!A2:A60,'Annual (first-hand)'!E2:E60,"<>") | D8: =INDEX('Annual (first-hand)'!E2:E60,MATCH(B8,'Annual (first-hand)'!A2:A60,0)) | E8: =MAX('Annual (first-hand)'!E2:E60) | F8: =INDEX('Annual (first-hand)'!A2:A60,MATCH(E8,'Annual (first-hand)'!E2:E60,0)) | G8: =INDEX('Annual (first-hand)'!E2:E60,MATCH(C8,'Annual (first-hand)'!A2:A60,0)) | H8: =E8/D8 | I8: =G8/E8-1 | J8: =F8-B8 | K8: =Summary!E8 | L8: =E8-K8
A9: Five hyperscalers (first-hand) | B9: =INDEX('Hyperscalers first-hand'!A10:A27,MATCH(TRUE,INDEX(ISNUMBER('Hyperscalers first-hand'!K10:K27),0),0)) | C9: =LOOKUP(2,1/ISNUMBER('Hyperscalers first-hand'!K10:K27),'Hyperscalers first-hand'!A10:A27) | D9: =INDEX('Hyperscalers first-hand'!K10:K27,MATCH(TRUE,INDEX(ISNUMBER('Hyperscalers first-hand'!K10:K27),0),0)) | E9: =MAX('Hyperscalers first-hand'!K10:K27) | F9: =INDEX('Hyperscalers first-hand'!A10:A27,MATCH(E9,'Hyperscalers first-hand'!K10:K27,0)) | G9: =LOOKUP(2,1/ISNUMBER('Hyperscalers first-hand'!K10:K27),'Hyperscalers first-hand'!K10:K27) | H9: =E9/D9 | I9: =G9/E9-1 | J9: =(MATCH(E9,'Hyperscalers first-hand'!K10:K27,0)-MATCH(TRUE,INDEX(ISNUMBER('Hyperscalers first-hand'!K10:K27),0),0))/4 | K9: =Summary!E9 | L9: =E9-K9
A10: Five + CoreWeave + Nebius + SpaceX AI (first-hand) | B10: =INDEX('Hyperscalers first-hand'!A17:A27,MATCH(TRUE,INDEX(ISNUMBER('Hyperscalers first-hand'!S17:S27),0),0)) | C10: =LOOKUP(2,1/ISNUMBER('Hyperscalers first-hand'!S17:S27),'Hyperscalers first-hand'!A17:A27) | D10: =INDEX('Hyperscalers first-hand'!S17:S27,MATCH(TRUE,INDEX(ISNUMBER('Hyperscalers first-hand'!S17:S27),0),0)) | E10: =MAX('Hyperscalers first-hand'!S17:S27) | F10: =INDEX('Hyperscalers first-hand'!A17:A27,MATCH(E10,'Hyperscalers first-hand'!S17:S27,0)) | G10: =LOOKUP(2,1/ISNUMBER('Hyperscalers first-hand'!S17:S27),'Hyperscalers first-hand'!S17:S27) | H10: =E10/D10 | I10: =G10/E10-1 | J10: =(MATCH(E10,'Hyperscalers first-hand'!S17:S27,0)-MATCH(TRUE,INDEX(ISNUMBER('Hyperscalers first-hand'!S17:S27),0),0))/4
A12: Annual series are calendar years (drawn as steps across each year). Hyperscalers are trailing-four-quarter capex over trailing-four-quarter GDP at the true quarter end, from the TTM to 2022Q1 (BofA's first point) to the latest filing; BofA draws the same numbers three quarters before their period end and stops at the TTM to 2026Q1, so its peak is one quarter older. BofA's lease-adjusted line cannot be rebuilt from filings; the second hyperscaler line adds CoreWeave, Nebius and SpaceX's AI segment instead, shown where the reported periods cover the four quarters (aligned on the five's start).

Sheet First-hand vs PDF
A1: Every panel rebuilt from the first-hand sources behind the footnote, compared with the PDF vector values
A3: Panel | B3: First-hand definition | C3: Points | D3: Max |diff| (pp) | E3: Mean |diff| (pp) | F3: Verdict
A4: Railroads | B4: NBER: Ulmer (1960) Table C-1 col.4 / Kuznets & Jenks (1961) R-22 col.1, R-2 col.7 (1929 prices) | C4: 22 | D4: =_xlfn.MAXIFS('First-hand detail'!$K$2:$K$79,'First-hand detail'!$A$2:$A$79,"rail") | E4: =AVERAGEIFS('First-hand detail'!$K$2:$K$79,'First-hand detail'!$A$2:$A$79,"rail") | F4: Exact
A5: O&G 1970s-80s | B5: BEA Fixed Assets: investment by industry 2110+2130+4860, all assets / GDP | C5: 15 | D5: =_xlfn.MAXIFS('First-hand detail'!$K$2:$K$79,'First-hand detail'!$A$2:$A$79,"og70s") | E5: =AVERAGEIFS('First-hand detail'!$K$2:$K$79,'First-hand detail'!$A$2:$A$79,"og70s") | F5: Exact
A6: O&G shale | B6: BEA Fixed Assets: investment by industry 2110+2130+4860, all assets / GDP | C6: 15 | D6: =_xlfn.MAXIFS('First-hand detail'!$K$2:$K$79,'First-hand detail'!$A$2:$A$79,"shale") | E6: =AVERAGEIFS('First-hand detail'!$K$2:$K$79,'First-hand detail'!$A$2:$A$79,"shale") | F6: Exact
A7: Telecoms | B7: BEA Fixed Assets: investment by industry 5130, all assets / GDP | C7: 9 | D7: =_xlfn.MAXIFS('First-hand detail'!$K$2:$K$79,'First-hand detail'!$A$2:$A$79,"telecom") | E7: =AVERAGEIFS('First-hand detail'!$K$2:$K$79,'First-hand detail'!$A$2:$A$79,"telecom") | F7: Exact
A8: Hyperscalers | B8: SEC XBRL capex MSFT+GOOGL+AMZN+META+ORCL, TTM / BEA GDP TTM | C8: 17 | D8: =_xlfn.MAXIFS('First-hand detail'!$K$2:$K$79,'First-hand detail'!$A$2:$A$79,"hyper") | E8: =AVERAGEIFS('First-hand detail'!$K$2:$K$79,'First-hand detail'!$A$2:$A$79,"hyper") | F8: Matches (RMSE 0.017pp, Oracle calendarised)
A9: Hyperscalers (lease adjusted) | B9: Not reproducible from filings: the gap to reported capex is 1-2.5x the finance-lease additions companies tag; finance + principal repayments or operating-lease additions do not fit either. Treat it as BofA's own estimate. | F9: Not reproducible
A11: Dating convention found in the process: every post-1970 point is drawn three quarters before the end of its four-quarter window (half a year before the start of its final quarter). A point drawn at position P
A12: is the four quarters ending at P+0.75: the hyperscaler point drawn at mid-2021 is TTM to 2022Q1, the last one (mid-2025)
A13: is TTM to 2026Q1. Annual year Y is drawn from Y-0.5 to Y+0.25 for the same reason.
A14: O&G is broader than drilling: BEA investment by the oil & gas extraction, support-activities-for-mining and pipeline
A15: industries, all asset types including intellectual property products. Telecoms is the broadcasting & telecoms industry, all assets.
A16: BEA vintage used here: Fixed Assets detailed investment updated 30 Sep 2026 and current NIPA GDP; identical to BofA's for these years.

Sheet First-hand detail
A1: Series | B1: Period | C1: Numerator | D1: Numerator unit | E1: Denominator | F1: Denominator unit | G1: Scale | H1: First-hand (% GDP) | I1: PDF vector (% GDP) | J1: Difference (pp) | K1: |Difference| | L1: First-hand source
A2: rail | B2: 1899 | C2: 405 | D2: $m, 1929 prices (C-1 col.4) | E2: 34.6 | F2: $bn, 1929 prices (GNP Variant I) | G2: 0.001 | H2: =C2*G2/E2*100 | I2: 1.169 | J2: =I2-H2 | K2: =ABS(J2) | L2: NBER: Ulmer (1960) Table C-1 col.4 / Kuznets & Jenks (1961) R-22 col.1, R-2 col.7 (1929 prices)
A3: rail | B3: 1900 | C3: 452 | D3: $m, 1929 prices (C-1 col.4) | E3: 36.2 | F3: $bn, 1929 prices (GNP Variant I) | G3: 0.001 | H3: =C3*G3/E3*100 | I3: 1.247 | J3: =I3-H3 | K3: =ABS(J3) | L3: NBER: Ulmer (1960) Table C-1 col.4 / Kuznets & Jenks (1961) R-22 col.1, R-2 col.7 (1929 prices)
A4: rail | B4: 1901 | C4: 414 | D4: $m, 1929 prices (C-1 col.4) | E4: 39.5 | F4: $bn, 1929 prices (GNP Variant I) | G4: 0.001 | H4: =C4*G4/E4*100 | I4: 1.047 | J4: =I4-H4 | K4: =ABS(J4) | L4: NBER: Ulmer (1960) Table C-1 col.4 / Kuznets & Jenks (1961) R-22 col.1, R-2 col.7 (1929 prices)
A5: rail | B5: 1902 | C5: 430 | D5: $m, 1929 prices (C-1 col.4) | E5: 40.2 | F5: $bn, 1929 prices (GNP Variant I) | G5: 0.001 | H5: =C5*G5/E5*100 | I5: 1.068 | J5: =I5-H5 | K5: =ABS(J5) | L5: NBER: Ulmer (1960) Table C-1 col.4 / Kuznets & Jenks (1961) R-22 col.1, R-2 col.7 (1929 prices)
A6: rail | B6: 1903 | C6: 452 | D6: $m, 1929 prices (C-1 col.4) | E6: 42.3 | F6: $bn, 1929 prices (GNP Variant I) | G6: 0.001 | H6: =C6*G6/E6*100 | I6: 1.068 | J6: =I6-H6 | K6: =ABS(J6) | L6: NBER: Ulmer (1960) Table C-1 col.4 / Kuznets & Jenks (1961) R-22 col.1, R-2 col.7 (1929 prices)
A7: rail | B7: 1904 | C7: 524 | D7: $m, 1929 prices (C-1 col.4) | E7: 41.8 | F7: $bn, 1929 prices (GNP Variant I) | G7: 0.001 | H7: =C7*G7/E7*100 | I7: 1.252 | J7: =I7-H7 | K7: =ABS(J7) | L7: NBER: Ulmer (1960) Table C-1 col.4 / Kuznets & Jenks (1961) R-22 col.1, R-2 col.7 (1929 prices)
A8: rail | B8: 1905 | C8: 662 | D8: $m, 1929 prices (C-1 col.4) | E8: 44.4 | F8: $bn, 1929 prices (GNP Variant I) | G8: 0.001 | H8: =C8*G8/E8*100 | I8: 1.49 | J8: =I8-H8 | K8: =ABS(J8) | L8: NBER: Ulmer (1960) Table C-1 col.4 / Kuznets & Jenks (1961) R-22 col.1, R-2 col.7 (1929 prices)
A9: rail | B9: 1906 | C9: 883 | D9: $m, 1929 prices (C-1 col.4) | E9: 49.1 | F9: $bn, 1929 prices (GNP Variant I) | G9: 0.001 | H9: =C9*G9/E9*100 | I9: 1.798 | J9: =I9-H9 | K9: =ABS(J9) | L9: NBER: Ulmer (1960) Table C-1 col.4 / Kuznets & Jenks (1961) R-22 col.1, R-2 col.7 (1929 prices)
A10: rail | B10: 1907 | C10: 1023 | D10: $m, 1929 prices (C-1 col.4) | E10: 50.5 | F10: $bn, 1929 prices (GNP Variant I) | G10: 0.001 | H10: =C10*G10/E10*100 | I10: 2.026 | J10: =I10-H10 | K10: =ABS(J10) | L10: NBER: Ulmer (1960) Table C-1 col.4 / Kuznets & Jenks (1961) R-22 col.1, R-2 col.7 (1929 prices)
A11: rail | B11: 1908 | C11: 1042 | D11: $m, 1929 prices (C-1 col.4) | E11: 46.9 | F11: $bn, 1929 prices (GNP Variant I) | G11: 0.001 | H11: =C11*G11/E11*100 | I11: 2.221 | J11: =I11-H11 | K11: =ABS(J11) | L11: NBER: Ulmer (1960) Table C-1 col.4 / Kuznets & Jenks (1961) R-22 col.1, R-2 col.7 (1929 prices)
A12: rail | B12: 1909 | C12: 1102 | D12: $m, 1929 prices (C-1 col.4) | E12: 52.1 | F12: $bn, 1929 prices (GNP Variant I) | G12: 0.001 | H12: =C12*G12/E12*100 | I12: 2.115 | J12: =I12-H12 | K12: =ABS(J12) | L12: NBER: Ulmer (1960) Table C-1 col.4 / Kuznets & Jenks (1961) R-22 col.1, R-2 col.7 (1929 prices)
A13: rail | B13: 1910 | C13: 1216 | D13: $m, 1929 prices (C-1 col.4) | E13: 52.8 | F13: $bn, 1929 prices (GNP Variant I) | G13: 0.001 | H13: =C13*G13/E13*100 | I13: 2.303 | J13: =I13-H13 | K13: =ABS(J13) | L13: NBER: Ulmer (1960) Table C-1 col.4 / Kuznets & Jenks (1961) R-22 col.1, R-2 col.7 (1929 prices)
... A62: telecom | B62: 2003 | C62: 90455 | D62: $m, BEA investment, industry 5130 | E62: 11456450 | F62: $m, BEA GDP (A191RC) | G62: 1 | H62: =C62*G62/E62*100 | I62: 0.789 | J62: =I62-H62 | K62: =ABS(J62) | L62: BEA Fixed Assets: investment by industry 5130, all assets / GDP
A63: hyper | B63: TTM to 2022Q1 | C63: ='Hyperscalers first-hand'!I10 | D63: $bn, TTM capex of the five (SEC) | E63: ='Hyperscalers first-hand'!J10 | F63: $bn, TTM BEA GDP | G63: 1 | H63: =C63*G63/E63*100 | I63: 0.537 | J63: =I63-H63 | K63: =ABS(J63) | L63: SEC XBRL capex MSFT+GOOGL+AMZN+META+ORCL, TTM / BEA GDP TTM
A64: hyper | B64: TTM to 2022Q2 | C64: ='Hyperscalers first-hand'!I11 | D64: $bn, TTM capex of the five (SEC) | E64: ='Hyperscalers first-hand'!J11 | F64: $bn, TTM BEA GDP | G64: 1 | H64: =C64*G64/E64*100 | I64: 0.564 | J64: =I64-H64 | K64: =ABS(J64) | L64: SEC XBRL capex MSFT+GOOGL+AMZN+META+ORCL, TTM / BEA GDP TTM
A65: hyper | B65: TTM to 2022Q3 | C65: ='Hyperscalers first-hand'!I12 | D65: $bn, TTM capex of the five (SEC) | E65: ='Hyperscalers first-hand'!J12 | F65: $bn, TTM BEA GDP | G65: 1 | H65: =C65*G65/E65*100 | I65: 0.595 | J65: =I65-H65 | K65: =ABS(J65) | L65: SEC XBRL capex MSFT+GOOGL+AMZN+META+ORCL, TTM / BEA GDP TTM
A66: hyper | B66: TTM to 2022Q4 | C66: ='Hyperscalers first-hand'!I13 | D66: $bn, TTM capex of the five (SEC) | E66: ='Hyperscalers first-hand'!J13 | F66: $bn, TTM BEA GDP | G66: 1 | H66: =C66*G66/E66*100 | I66: 0.611 | J66: =I66-H66 | K66: =ABS(J66) | L66: SEC XBRL capex MSFT+GOOGL+AMZN+META+ORCL, TTM / BEA GDP TTM
A67: hyper | B67: TTM to 2023Q1 | C67: ='Hyperscalers first-hand'!I14 | D67: $bn, TTM capex of the five (SEC) | E67: ='Hyperscalers first-hand'!J14 | F67: $bn, TTM BEA GDP | G67: 1 | H67: =C67*G67/E67*100 | I67: 0.569 | J67: =I67-H67 | K67: =ABS(J67) | L67: SEC XBRL capex MSFT+GOOGL+AMZN+META+ORCL, TTM / BEA GDP TTM
A68: hyper | B68: TTM to 2023Q2 | C68: ='Hyperscalers first-hand'!I15 | D68: $bn, TTM capex of the five (SEC) | E68: ='Hyperscalers first-hand'!J15 | F68: $bn, TTM BEA GDP | G68: 1 | H68: =C68*G68/E68*100 | I68: 0.555 | J68: =I68-H68 | K68: =ABS(J68) | L68: SEC XBRL capex MSFT+GOOGL+AMZN+META+ORCL, TTM / BEA GDP TTM
A69: hyper | B69: TTM to 2023Q3 | C69: ='Hyperscalers first-hand'!I16 | D69: $bn, TTM capex of the five (SEC) | E69: ='Hyperscalers first-hand'!J16 | F69: $bn, TTM BEA GDP | G69: 1 | H69: =C69*G69/E69*100 | I69: 0.542 | J69: =I69-H69 | K69: =ABS(J69) | L69: SEC XBRL capex MSFT+GOOGL+AMZN+META+ORCL, TTM / BEA GDP TTM
A70: hyper | B70: TTM to 2023Q4 | C70: ='Hyperscalers first-hand'!I17 | D70: $bn, TTM capex of the five (SEC) | E70: ='Hyperscalers first-hand'!J17 | F70: $bn, TTM BEA GDP | G70: 1 | H70: =C70*G70/E70*100 | I70: 0.551 | J70: =I70-H70 | K70: =ABS(J70) | L70: SEC XBRL capex MSFT+GOOGL+AMZN+META+ORCL, TTM / BEA GDP TTM
A71: hyper | B71: TTM to 2024Q1 | C71: ='Hyperscalers first-hand'!I18 | D71: $bn, TTM capex of the five (SEC) | E71: ='Hyperscalers first-hand'!J18 | F71: $bn, TTM BEA GDP | G71: 1 | H71: =C71*G71/E71*100 | I71: 0.562 | J71: =I71-H71 | K71: =ABS(J71) | L71: SEC XBRL capex MSFT+GOOGL+AMZN+META+ORCL, TTM / BEA GDP TTM
A72: hyper | B72: TTM to 2024Q2 | C72: ='Hyperscalers first-hand'!I19 | D72: $bn, TTM capex of the five (SEC) | E72: ='Hyperscalers first-hand'!J19 | F72: $bn, TTM BEA GDP | G72: 1 | H72: =C72*G72/E72*100 | I72: 0.63 | J72: =I72-H72 | K72: =ABS(J72) | L72: SEC XBRL capex MSFT+GOOGL+AMZN+META+ORCL, TTM / BEA GDP TTM
A73: hyper | B73: TTM to 2024Q3 | C73: ='Hyperscalers first-hand'!I20 | D73: $bn, TTM capex of the five (SEC) | E73: ='Hyperscalers first-hand'!J20 | F73: $bn, TTM BEA GDP | G73: 1 | H73: =C73*G73/E73*100 | I73: 0.715 | J73: =I73-H73 | K73: =ABS(J73) | L73: SEC XBRL capex MSFT+GOOGL+AMZN+META+ORCL, TTM / BEA GDP TTM
A74: hyper | B74: TTM to 2024Q4 | C74: ='Hyperscalers first-hand'!I21 | D74: $bn, TTM capex of the five (SEC) | E74: ='Hyperscalers first-hand'!J21 | F74: $bn, TTM BEA GDP | G74: 1 | H74: =C74*G74/E74*100 | I74: 0.829 | J74: =I74-H74 | K74: =ABS(J74) | L74: SEC XBRL capex MSFT+GOOGL+AMZN+META+ORCL, TTM / BEA GDP TTM
... A79: hyper | B79: TTM to 2026Q1 | C79: ='Hyperscalers first-hand'!I26 | D79: $bn, TTM capex of the five (SEC) | E79: ='Hyperscalers first-hand'!J26 | F79: $bn, TTM BEA GDP | G79: 1 | H79: =C79*G79/E79*100 | I79: 1.536 | J79: =I79-H79 | K79: =ABS(J79) | L79: SEC XBRL capex MSFT+GOOGL+AMZN+META+ORCL, TTM / BEA GDP TTM

Sheet Chart points
A1: Series | B1: Label | C1: Chart position (year) | D1: Years since cycle start | E1: % of US GDP | F1: Year (annual series)
A2: rail | B2: US railroads (1900 onwards) | C2: 1899 | D2: =C2-C2 | E2: 1.169 | F2: 1899
A3: rail | B3: US railroads (1900 onwards) | C3: 1900 | D3: =C3-C2 | E3: 1.247 | F3: 1900
A4: rail | B4: US railroads (1900 onwards) | C4: 1901 | D4: =C4-C2 | E4: 1.047 | F4: 1901
A5: rail | B5: US railroads (1900 onwards) | C5: 1902 | D5: =C5-C2 | E5: 1.068 | F5: 1902
A6: rail | B6: US railroads (1900 onwards) | C6: 1903 | D6: =C6-C2 | E6: 1.068 | F6: 1903
A7: rail | B7: US railroads (1900 onwards) | C7: 1904 | D7: =C7-C2 | E7: 1.252 | F7: 1904
A8: rail | B8: US railroads (1900 onwards) | C8: 1905 | D8: =C8-C2 | E8: 1.49 | F8: 1905
A9: rail | B9: US railroads (1900 onwards) | C9: 1906 | D9: =C9-C2 | E9: 1.798 | F9: 1906
A10: rail | B10: US railroads (1900 onwards) | C10: 1907 | D10: =C10-C2 | E10: 2.026 | F10: 1907
A11: rail | B11: US railroads (1900 onwards) | C11: 1908 | D11: =C11-C2 | E11: 2.221 | F11: 1908
A12: rail | B12: US railroads (1900 onwards) | C12: 1909 | D12: =C12-C2 | E12: 2.115 | F12: 1909
A13: rail | B13: US railroads (1900 onwards) | C13: 1910 | D13: =C13-C2 | E13: 2.303 | F13: 1910
A14: rail | B14: US railroads (1900 onwards) | C14: 1911 | D14: =C14-C2 | E14: 2.117 | F14: 1911
A15: rail | B15: US railroads (1900 onwards) | C15: 1912 | D15: =C15-C2 | E15: 1.998 | F15: 1912
A16: rail | B16: US railroads (1900 onwards) | C16: 1913 | D16: =C16-C2 | E16: 1.979 | F16: 1913
A17: rail | B17: US railroads (1900 onwards) | C17: 1914 | D17: =C17-C2 | E17: 1.418 | F17: 1914
A18: rail | B18: US railroads (1900 onwards) | C18: 1915 | D18: =C18-C2 | E18: 0.79 | F18: 1915
A19: rail | B19: US railroads (1900 onwards) | C19: 1916 | D19: =C19-C2 | E19: 0.816 | F19: 1916
A20: rail | B20: US railroads (1900 onwards) | C20: 1917 | D20: =C20-C2 | E20: 1.013 | F20: 1917
A21: rail | B21: US railroads (1900 onwards) | C21: 1918 | D21: =C21-C2 | E21: 0.78 | F21: 1918
A22: rail | B22: US railroads (1900 onwards) | C22: 1919 | D22: =C22-C2 | E22: 0.508 | F22: 1919
A23: rail | B23: US railroads (1900 onwards) | C23: 1920 | D23: =C23-C2 | E23: 0.726 | F23: 1920
A24: og70s | B24: O&G (1970-80s) | C24: 1972 | D24: =C24-C24 | E24: 0.379 | F24: 1972
A25: og70s | B25: O&G (1970-80s) | C25: 1972.25 | D25: =C25-C24 | E25: 0.379 | F25: 1972
A26: og70s | B26: O&G (1970-80s) | C26: 1972.5 | D26: =C26-C24 | E26: 0.391 | F26: 1973
A27: og70s | B27: O&G (1970-80s) | C27: 1972.75 | D27: =C27-C24 | E27: 0.391 | F27: 1973
A28: og70s | B28: O&G (1970-80s) | C28: 1973 | D28: =C28-C24 | E28: 0.391 | F28: 1973
A29: og70s | B29: O&G (1970-80s) | C29: 1973.25 | D29: =C29-C24 | E29: 0.391 | F29: 1973
A30: og70s | B30: O&G (1970-80s) | C30: 1973.5 | D30: =C30-C24 | E30: 0.495 | F30: 1974
A31: og70s | B31: O&G (1970-80s) | C31: 1973.75 | D31: =C31-C24 | E31: 0.495 | F31: 1974
A32: og70s | B32: O&G (1970-80s) | C32: 1974 | D32: =C32-C24 | E32: 0.495 | F32: 1974
A33: og70s | B33: O&G (1970-80s) | C33: 1974.25 | D33: =C33-C24 | E33: 0.495 | F33: 1974
A34: og70s | B34: O&G (1970-80s) | C34: 1974.5 | D34: =C34-C24 | E34: 0.665 | F34: 1975
A35: og70s | B35: O&G (1970-80s) | C35: 1974.75 | D35: =C35-C24 | E35: 0.665 | F35: 1975
A36: og70s | B36: O&G (1970-80s) | C36: 1975 | D36: =C36-C24 | E36: 0.665 | F36: 1975
A37: og70s | B37: O&G (1970-80s) | C37: 1975.25 | D37: =C37-C24 | E37: 0.665 | F37: 1975
A38: og70s | B38: O&G (1970-80s) | C38: 1975.5 | D38: =C38-C24 | E38: 0.7 | F38: 1976
A39: og70s | B39: O&G (1970-80s) | C39: 1975.75 | D39: =C39-C24 | E39: 0.7 | F39: 1976
A40: og70s | B40: O&G (1970-80s) | C40: 1976 | D40: =C40-C24 | E40: 0.7 | F40: 1976
...

Sheet Annual
A1: Year | B1: US railroads (1900 onwards) | C1: O&G (1970-80s) | D1: Telecoms (1990s) | E1: O&G (Shale)
A2: 1899 | B2: 1.169
A3: 1900 | B3: 1.247
A4: 1901 | B4: 1.047
A5: 1902 | B5: 1.068
A6: 1903 | B6: 1.068
A7: 1904 | B7: 1.252
A8: 1905 | B8: 1.49
A9: 1906 | B9: 1.798
A10: 1907 | B10: 2.026
A11: 1908 | B11: 2.221
A12: 1909 | B12: 2.115
A13: 1910 | B13: 2.303
... A23: 1920 | B23: 0.726
A24: 1972 | C24: 0.379
A25: 1973 | C25: 0.391
A26: 1974 | C26: 0.495
A27: 1975 | C27: 0.665
A28: 1976 | C28: 0.7
A29: 1977 | C29: 0.722
A30: 1978 | C30: 0.909
A31: 1979 | C31: 1.064
A32: 1980 | C32: 1.425
A33: 1981 | C33: 1.972
A34: 1982 | C34: 1.891
A35: 1983 | C35: 1.182
... A38: 1986 | C38: 0.516
A39: 1995 | D39: 1.054
A40: 1996 | D40: 1.083
A41: 1997 | D41: 1.098
A42: 1998 | D42: 1.135
A43: 1999 | D43: 1.285
A44: 2000 | D44: 1.54
A45: 2001 | D45: 1.337
A46: 2002 | D46: 0.91 | E46: 0.395
A47: 2003 | D47: 0.789 | E47: 0.468
A48: 2004 | E48: 0.505
A49: 2005 | E49: 0.653
A50: 2006 | E50: 0.866
A51: 2007 | E51: 0.95
...

Sheet Hyperscalers
A1: Trailing 4 quarters to | B1: Position (year) | C1: Hyperscalers | D1: Hyperscalers (lease adjusted) | E1: Lease adjustment (pp)
A2: TTM to 2022Q1 | B2: 2021.5 | C2: 0.537 | D2: 0.616 | E2: =D2-C2
A3: TTM to 2022Q2 | B3: 2021.75 | C3: 0.564 | D3: 0.637 | E3: =D3-C3
A4: TTM to 2022Q3 | B4: 2022 | C4: 0.595 | D4: 0.64 | E4: =D4-C4
A5: TTM to 2022Q4 | B5: 2022.25 | C5: 0.611 | D5: 0.655 | E5: =D5-C5
A6: TTM to 2023Q1 | B6: 2022.5 | C6: 0.569 | D6: 0.627 | E6: =D6-C6
A7: TTM to 2023Q2 | B7: 2022.75 | C7: 0.555 | D7: 0.614 | E7: =D7-C7
A8: TTM to 2023Q3 | B8: 2023 | C8: 0.542 | D8: 0.592 | E8: =D8-C8
A9: TTM to 2023Q4 | B9: 2023.25 | C9: 0.551 | D9: 0.595 | E9: =D9-C9
A10: TTM to 2024Q1 | B10: 2023.5 | C10: 0.562 | D10: 0.596 | E10: =D10-C10
A11: TTM to 2024Q2 | B11: 2023.75 | C11: 0.63 | D11: 0.686 | E11: =D11-C11
A12: TTM to 2024Q3 | B12: 2024 | C12: 0.715 | D12: 0.78 | E12: =D12-C12
A13: TTM to 2024Q4 | B13: 2024.25 | C13: 0.829 | D13: 0.896 | E13: =D13-C13
... A18: TTM to 2026Q1 | B18: 2025.5 | C18: 1.536 | D18: 1.702 | E18: =D18-C18

Sheet Oracle fiscal quarters
A1: Fiscal quarter ends | B1: Oracle capex ($bn) | C1: Months covered
A2: 2019-11-30 | B2: 0.349 | C2: Sep 2019 - Nov 2019
A3: 2020-02-29 | B3: 0.396 | C3: Dec 2019 - Feb 2020
A4: 2020-05-31 | B4: 0.433 | C4: Mar 2020 - May 2020
A5: 2020-08-31 | B5: 0.436 | C5: Jun 2020 - Aug 2020
A6: 2020-11-30 | B6: 0.568 | C6: Sep 2020 - Nov 2020
A7: 2021-02-28 | B7: 0.414 | C7: Dec 2020 - Feb 2021
A8: 2021-05-31 | B8: 0.717 | C8: Mar 2021 - May 2021
A9: 2021-08-31 | B9: 1.062 | C9: Jun 2021 - Aug 2021
A10: 2021-11-30 | B10: 0.925 | C10: Sep 2021 - Nov 2021
A11: 2022-02-28 | B11: 1.101 | C11: Dec 2021 - Feb 2022
A12: 2022-05-31 | B12: 1.423 | C12: Mar 2022 - May 2022
A13: 2022-08-31 | B13: 1.719 | C13: Jun 2022 - Aug 2022
... A29: 2026-08-31 | B29: 28.499 | C29: Jun 2026 - Aug 2026
A31: Discrete quarters from Oracle's 10-Q year-to-date cash flows (Q4 = fiscal year minus 9 months), SEC XBRL PaymentsToAcquirePropertyPlantAndEquipment. Fiscal year ends 31 May.

Sheet Hyperscalers first-hand
A1: Calendar quarter | B1: MSFT | C1: GOOGL | D1: AMZN | E1: META | F1: ORCL (calendarised) | G1: Capex, 5 names | H1: BEA GDP, SAAR | I1: TTM capex | J1: TTM GDP | K1: TTM capex % of GDP | L1: BofA chart (PDF) | M1: BofA - first-hand (pp) | N1: CoreWeave | O1: Nebius | P1: SpaceX AI segment | Q1: Reported period (if not one quarter) | R1: TTM capex, 8 names | S1: TTM 8 names % of GDP | U1: All $bn. Blue = inputs as filed (SEC 10-Q/10-K/20-F/6-K, SpaceX IPO prospectus, BEA NIPA A191RC); black = formulas. Columns B-M = BofA's five-name definition; N-S add CoreWeave, Nebius and SpaceX's AI segment (xAI).
A2: 2020Q1 | B2: 3.767 | C2: 6.005 | D2: 6.795 | E2: 3.558 | F2: =2/3*'Oracle fiscal quarters'!B3+1/3*'Oracle fiscal quarters'!B4 | G2: =SUM(B2:F2) | H2: 21751.238
A3: 2020Q2 | B3: 4.744 | C3: 5.391 | D3: 7.459 | E3: 3.255 | F3: =2/3*'Oracle fiscal quarters'!B4+1/3*'Oracle fiscal quarters'!B5 | G3: =SUM(B3:F3) | H3: 19958.291
A4: 2020Q3 | B4: 4.907 | C4: 5.406 | D4: 11.063 | E4: 3.689 | F4: =2/3*'Oracle fiscal quarters'!B5+1/3*'Oracle fiscal quarters'!B6 | G4: =SUM(B4:F4) | H4: 21704.437
A5: 2020Q4 | B5: 4.174 | C5: 5.479 | D5: 14.823 | E5: 4.661 | F5: =2/3*'Oracle fiscal quarters'!B6+1/3*'Oracle fiscal quarters'!B7 | G5: =SUM(B5:F5) | H5: 22087.16 | I5: =SUM(G2:G5) | J5: =AVERAGE(H2:H5) | K5: =I5/J5*100
A6: 2021Q1 | B6: 5.089 | C6: 5.942 | D6: 12.082 | E6: 4.303 | F6: =2/3*'Oracle fiscal quarters'!B7+1/3*'Oracle fiscal quarters'!B8 | G6: =SUM(B6:F6) | H6: 22704.65 | I6: =SUM(G3:G6) | J6: =AVERAGE(H3:H6) | K6: =I6/J6*100
A7: 2021Q2 | B7: 6.452 | C7: 5.496 | D7: 14.288 | E7: 4.641 | F7: =2/3*'Oracle fiscal quarters'!B8+1/3*'Oracle fiscal quarters'!B9 | G7: =SUM(B7:F7) | H7: 23456.708 | I7: =SUM(G4:G7) | J7: =AVERAGE(H4:H7) | K7: =I7/J7*100
A8: 2021Q3 | B8: 5.81 | C8: 6.819 | D8: 15.748 | E8: 4.346 | F8: =2/3*'Oracle fiscal quarters'!B9+1/3*'Oracle fiscal quarters'!B10 | G8: =SUM(B8:F8) | H8: 23998.844 | I8: =SUM(G5:G8) | J8: =AVERAGE(H5:H8) | K8: =I8/J8*100
A9: 2021Q4 | B9: 5.865 | C9: 6.383 | D9: 18.935 | E9: 5.4 | F9: =2/3*'Oracle fiscal quarters'!B10+1/3*'Oracle fiscal quarters'!B11 | G9: =SUM(B9:F9) | H9: 24823.19 | I9: =SUM(G6:G9) | J9: =AVERAGE(H6:H9) | K9: =I9/J9*100
A10: 2022Q1 | B10: 5.34 | C10: 9.786 | D10: 14.951 | E10: 5.441 | F10: =2/3*'Oracle fiscal quarters'!B11+1/3*'Oracle fiscal quarters'!B12 | G10: =SUM(B10:F10) | H10: 25259.992 | I10: =SUM(G7:G10) | J10: =AVERAGE(H7:H10) | K10: =I10/J10*100 | L10: 0.537 | M10: =L10-K10
A11: 2022Q2 | B11: 6.871 | C11: 6.828 | D11: 15.724 | E11: 7.572 | F11: =2/3*'Oracle fiscal quarters'!B12+1/3*'Oracle fiscal quarters'!B13 | G11: =SUM(B11:F11) | H11: 25869.353 | I11: =SUM(G8:G11) | J11: =AVERAGE(H8:H11) | K11: =I11/J11*100 | L11: 0.564 | M11: =L11-K11
A12: 2022Q3 | B12: 6.283 | C12: 7.276 | D12: 16.378 | E12: 9.375 | F12: =2/3*'Oracle fiscal quarters'!B13+1/3*'Oracle fiscal quarters'!B14 | G12: =SUM(B12:F12) | H12: 26335.374 | I12: =SUM(G9:G12) | J12: =AVERAGE(H9:H12) | K12: =I12/J12*100 | L12: 0.595 | M12: =L12-K12
A13: 2022Q4 | B13: 6.274 | C13: 7.595 | D13: 16.592 | E13: 8.798 | F13: =2/3*'Oracle fiscal quarters'!B14+1/3*'Oracle fiscal quarters'!B15 | G13: =SUM(B13:F13) | H13: 26774.117 | I13: =SUM(G10:G13) | J13: =AVERAGE(H10:H13) | K13: =I13/J13*100 | L13: 0.611 | M13: =L13-K13
A14: 2023Q1 | B14: 6.607 | C14: 6.289 | D14: 14.207 | E14: 6.823 | F14: =2/3*'Oracle fiscal quarters'!B15+1/3*'Oracle fiscal quarters'!B16 | G14: =SUM(B14:F14) | H14: 27241.282 | I14: =SUM(G11:G14) | J14: =AVERAGE(H11:H14) | K14: =I14/J14*100 | L14: 0.569 | M14: =L14-K14
A15: 2023Q2 | B15: 8.943 | C15: 6.888 | D15: 11.455 | E15: 6.134 | F15: =2/3*'Oracle fiscal quarters'!B16+1/3*'Oracle fiscal quarters'!B17 | G15: =SUM(B15:F15) | H15: 27533.925 | I15: =SUM(G12:G15) | J15: =AVERAGE(H12:H15) | K15: =I15/J15*100 | L15: 0.555 | M15: =L15-K15
A16: 2023Q3 | B16: 9.917 | C16: 8.055 | D16: 12.479 | E16: 6.496 | F16: =2/3*'Oracle fiscal quarters'!B17+1/3*'Oracle fiscal quarters'!B18 | G16: =SUM(B16:F16) | H16: 28064.032 | I16: =SUM(G13:G16) | J16: =AVERAGE(H13:H16) | K16: =I16/J16*100 | L16: 0.542 | M16: =L16-K16
A17: 2023Q4 | B17: 9.735 | C17: 11.019 | D17: 14.588 | E17: 7.592 | F17: =2/3*'Oracle fiscal quarters'!B18+1/3*'Oracle fiscal quarters'!B19 | G17: =SUM(B17:F17) | H17: 28464.306 | I17: =SUM(G14:G17) | J17: =AVERAGE(H14:H17) | K17: =I17/J17*100 | L17: 0.551 | M17: =L17-K17 | N17: 2.943 | O17: 0.0829 | P17: 0.463 | Q17: CoreWeave: FY2023; Nebius: FY2023; SpaceX AI: FY2023 | R17: =I17+SUM(N14:N17)+SUM(O14:O17)+SUM(P14:P17) | S17: =R17/J17*100
A18: 2024Q1 | B18: 10.952 | C18: 12.012 | D18: 14.925 | E18: 6.4 | F18: =2/3*'Oracle fiscal quarters'!B19+1/3*'Oracle fiscal quarters'!B20 | G18: =SUM(B18:F18) | H18: 28793.191 | I18: =SUM(G15:G18) | J18: =AVERAGE(H15:H18) | K18: =I18/J18*100 | L18: 0.562 | M18: =L18-K18 | N18: 1.7419
A19: 2024Q2 | B19: 13.873 | C19: 13.186 | D19: 17.62 | E19: 8.173 | F19: =2/3*'Oracle fiscal quarters'!B20+1/3*'Oracle fiscal quarters'!B21 | G19: =SUM(B19:F19) | H19: 29232.964 | I19: =SUM(G16:G19) | J19: =AVERAGE(H16:H19) | K19: =I19/J19*100 | L19: 0.63 | M19: =L19-K19 | N19: 2.2472
A20: 2024Q3 | B20: 14.923 | C20: 13.061 | D20: 22.62 | E20: 8.258 | F20: =2/3*'Oracle fiscal quarters'!B21+1/3*'Oracle fiscal quarters'!B22 | G20: =SUM(B20:F20) | H20: 29568.256 | I20: =SUM(G17:G20) | J20: =AVERAGE(H17:H20) | K20: =I20/J20*100 | L20: 0.715 | M20: =L20-K20 | N20: 1.2152 | O20: 0.39 | Q20: Nebius: 2024Q1-2024Q3
A21: 2024Q4 | B21: 15.804 | C21: 14.276 | D21: 27.834 | E21: 14.425 | F21: =2/3*'Oracle fiscal quarters'!B22+1/3*'Oracle fiscal quarters'!B23 | G21: =SUM(B21:F21) | H21: 29929.552 | I21: =SUM(G18:G21) | J21: =AVERAGE(H18:H21) | K21: =I21/J21*100 | L21: 0.829 | M21: =L21-K21 | N21: 3.4977 | O21: 0.4175 | P21: 5.633 | Q21: SpaceX AI: FY2024 | R21: =I21+SUM(N18:N21)+SUM(O18:O21)+SUM(P18:P21) | S21: =R21/J21*100
A22: 2025Q1 | B22: 16.745 | C22: 17.197 | D22: 25.019 | E22: 12.941 | F22: =2/3*'Oracle fiscal quarters'!B23+1/3*'Oracle fiscal quarters'!B24 | G22: =SUM(B22:F22) | H22: 30171.979 | I22: =SUM(G19:G22) | J22: =AVERAGE(H19:H22) | K22: =I22/J22*100 | L22: 0.901 | M22: =L22-K22 | N22: 1.407 | O22: 0.5439 | P22: 2.567
A23: 2025Q2 | B23: 17.079 | C23: 22.446 | D23: 32.183 | E23: 16.538 | F23: =2/3*'Oracle fiscal quarters'!B24+1/3*'Oracle fiscal quarters'!B25 | G23: =SUM(B23:F23) | H23: 30630.174 | I23: =SUM(G20:G23) | J23: =AVERAGE(H20:H23) | K23: =I23/J23*100 | L23: 1.036 | M23: =L23-K23 | N23: 2.453 | O23: 0.5106 | P23: 0.749
A24: 2025Q3 | B24: 19.394 | C24: 23.953 | D24: 35.095 | E24: 18.829 | F24: =2/3*'Oracle fiscal quarters'!B25+1/3*'Oracle fiscal quarters'!B26 | G24: =SUM(B24:F24) | H24: 31180.493 | I24: =SUM(G21:G24) | J24: =AVERAGE(H21:H24) | K24: =I24/J24*100 | L24: 1.187 | M24: =L24-K24 | N24: 2.3892 | O24: 0.9555 | P24: 4.76
A25: 2025Q4 | B25: 29.876 | C25: 27.851 | D25: 39.522 | E25: 21.383 | F25: =2/3*'Oracle fiscal quarters'!B26+1/3*'Oracle fiscal quarters'!B27 | G25: =SUM(B25:F25) | H25: 31462.523 | I25: =SUM(G22:G25) | J25: =AVERAGE(H22:H25) | K25: =I25/J25*100 | L25: 1.379 | M25: =L25-K25 | N25: 4.0598 | O25: 2.056 | P25: 4.65 | R25: =I25+SUM(N22:N25)+SUM(O22:O25)+SUM(P22:P25) | S25: =R25/J25*100
A26: 2026Q1 | B26: 30.876 | C26: 35.674 | D26: 44.203 | E26: 18.997 | F26: =2/3*'Oracle fiscal quarters'!B27+1/3*'Oracle fiscal quarters'!B28 | G26: =SUM(B26:F26) | H26: 31906.274 | I26: =SUM(G23:G26) | J26: =AVERAGE(H23:H26) | K26: =I26/J26*100 | L26: 1.536 | M26: =L26-K26 | N26: 7.695 | O26: 2.4729 | P26: 7.723 | R26: =I26+SUM(N23:N26)+SUM(O23:O26)+SUM(P23:P26) | S26: =R26/J26*100
A27: 2026Q2 | B27: 35.802 | C27: 44.924 | D27: 54.208 | E27: 30.116 | F27: =2/3*'Oracle fiscal quarters'!B28+1/3*'Oracle fiscal quarters'!B29 | G27: =SUM(B27:F27) | H27: 32563.03 | I27: =SUM(G24:G27) | J27: =AVERAGE(H24:H27) | K27: =I27/J27*100 | N27: 6.422 | O27: 5.6574 | P27: 15.828 | R27: =I27+SUM(N24:N27)+SUM(O24:O27)+SUM(P24:P27) | S27: =R27/J27*100
A29: Oracle's fiscal quarters end Feb/May/Aug/Nov; each calendar quarter = 2/3 x the Oracle quarter ending in its second month + 1/3 x the next Oracle quarter (Oracle fiscal quarters sheet). The others end on calendar quarter ends (Microsoft's June fiscal year included). Discrete quarters come from year-to-date cash flows (Q4 = year minus 9 months).
A30: BofA's chart: each point is drawn three quarters before the end of its four-quarter window (half a year before the start of its final quarter); its last point (drawn at mid-2025) is the TTM to 2026Q1.
A31: CoreWeave: SEC XBRL purchases of property & equipment (quarterly from 2024, FY2023 annual). Nebius: 20-F XBRL fiscal years and 6-K interim statements / earnings releases (purchases of property and equipment and intangible assets; 9M 2024 is one period). SpaceX AI segment (xAI): segment capital expenditures, SpaceX IPO prospectus 424B4 (12 Jun 2026) for FY2023, FY2024, Q1 2025, FY2025 and Q1 2026, 10-Q XBRL (SegmentExpenditureAdditionToLongLivedAssets, AI segment) after. SpaceX never reported Q3 or Q4 2025 alone, so H2 2025 (= FY2025 - H1 2025) is one period in the 2025Q4 row; 7-name TTM is shown only where periods tile the window.

Sheet Annual (first-hand)
A1: Year | B1: US railroads (1900 onwards) | C1: O&G (1970-80s) | D1: Telecoms (1990s) | E1: O&G (Shale)
A2: 1899 | B2: ='First-hand detail'!H2
A3: 1900 | B3: ='First-hand detail'!H3
A4: 1901 | B4: ='First-hand detail'!H4
A5: 1902 | B5: ='First-hand detail'!H5
A6: 1903 | B6: ='First-hand detail'!H6
A7: 1904 | B7: ='First-hand detail'!H7
A8: 1905 | B8: ='First-hand detail'!H8
A9: 1906 | B9: ='First-hand detail'!H9
A10: 1907 | B10: ='First-hand detail'!H10
A11: 1908 | B11: ='First-hand detail'!H11
A12: 1909 | B12: ='First-hand detail'!H12
A13: 1910 | B13: ='First-hand detail'!H13
... A23: 1920 | B23: ='First-hand detail'!H23
A24: 1972 | C24: ='First-hand detail'!H24
A25: 1973 | C25: ='First-hand detail'!H25
A26: 1974 | C26: ='First-hand detail'!H26
A27: 1975 | C27: ='First-hand detail'!H27
A28: 1976 | C28: ='First-hand detail'!H28
A29: 1977 | C29: ='First-hand detail'!H29
A30: 1978 | C30: ='First-hand detail'!H30
A31: 1979 | C31: ='First-hand detail'!H31
A32: 1980 | C32: ='First-hand detail'!H32
A33: 1981 | C33: ='First-hand detail'!H33
A34: 1982 | C34: ='First-hand detail'!H34
A35: 1983 | C35: ='First-hand detail'!H35
... A38: 1986 | C38: ='First-hand detail'!H38
A39: 1995 | D39: ='First-hand detail'!H54
A40: 1996 | D40: ='First-hand detail'!H55
A41: 1997 | D41: ='First-hand detail'!H56
A42: 1998 | D42: ='First-hand detail'!H57
A43: 1999 | D43: ='First-hand detail'!H58
A44: 2000 | D44: ='First-hand detail'!H59
A45: 2001 | D45: ='First-hand detail'!H60
A46: 2002 | D46: ='First-hand detail'!H61 | E46: ='First-hand detail'!H39
A47: 2003 | D47: ='First-hand detail'!H62 | E47: ='First-hand detail'!H40
A48: 2004 | E48: ='First-hand detail'!H41
A49: 2005 | E49: ='First-hand detail'!H42
A50: 2006 | E50: ='First-hand detail'!H43
A51: 2007 | E51: ='First-hand detail'!H44
...

Sheet Chart points (first-hand)
A1: Series | B1: Label | C1: Calendar position (year) | D1: Years since cycle start | E1: % of US GDP
A2: rail | B2: US railroads (1900 onwards) | C2: 1899 | D2: =C2-C2 | E2: ='First-hand detail'!H2
A3: rail | B3: US railroads (1900 onwards) | C3: 1900 | D3: =C3-C2 | E3: ='First-hand detail'!H3
A4: rail | B4: US railroads (1900 onwards) | C4: 1901 | D4: =C4-C2 | E4: ='First-hand detail'!H4
A5: rail | B5: US railroads (1900 onwards) | C5: 1902 | D5: =C5-C2 | E5: ='First-hand detail'!H5
A6: rail | B6: US railroads (1900 onwards) | C6: 1903 | D6: =C6-C2 | E6: ='First-hand detail'!H6
A7: rail | B7: US railroads (1900 onwards) | C7: 1904 | D7: =C7-C2 | E7: ='First-hand detail'!H7
A8: rail | B8: US railroads (1900 onwards) | C8: 1905 | D8: =C8-C2 | E8: ='First-hand detail'!H8
A9: rail | B9: US railroads (1900 onwards) | C9: 1906 | D9: =C9-C2 | E9: ='First-hand detail'!H9
A10: rail | B10: US railroads (1900 onwards) | C10: 1907 | D10: =C10-C2 | E10: ='First-hand detail'!H10
A11: rail | B11: US railroads (1900 onwards) | C11: 1908 | D11: =C11-C2 | E11: ='First-hand detail'!H11
A12: rail | B12: US railroads (1900 onwards) | C12: 1909 | D12: =C12-C2 | E12: ='First-hand detail'!H12
A13: rail | B13: US railroads (1900 onwards) | C13: 1910 | D13: =C13-C2 | E13: ='First-hand detail'!H13
A14: rail | B14: US railroads (1900 onwards) | C14: 1911 | D14: =C14-C2 | E14: ='First-hand detail'!H14
A15: rail | B15: US railroads (1900 onwards) | C15: 1912 | D15: =C15-C2 | E15: ='First-hand detail'!H15
A16: rail | B16: US railroads (1900 onwards) | C16: 1913 | D16: =C16-C2 | E16: ='First-hand detail'!H16
A17: rail | B17: US railroads (1900 onwards) | C17: 1914 | D17: =C17-C2 | E17: ='First-hand detail'!H17
A18: rail | B18: US railroads (1900 onwards) | C18: 1915 | D18: =C18-C2 | E18: ='First-hand detail'!H18
A19: rail | B19: US railroads (1900 onwards) | C19: 1916 | D19: =C19-C2 | E19: ='First-hand detail'!H19
A20: rail | B20: US railroads (1900 onwards) | C20: 1917 | D20: =C20-C2 | E20: ='First-hand detail'!H20
A21: rail | B21: US railroads (1900 onwards) | C21: 1918 | D21: =C21-C2 | E21: ='First-hand detail'!H21
A22: rail | B22: US railroads (1900 onwards) | C22: 1919 | D22: =C22-C2 | E22: ='First-hand detail'!H22
A23: rail | B23: US railroads (1900 onwards) | C23: 1920 | D23: =C23-C2 | E23: ='First-hand detail'!H23
A24: og70s | B24: O&G (1970-80s) | C24: 1972 | D24: =C24-C24 | E24: ='First-hand detail'!H24
A25: og70s | B25: O&G (1970-80s) | C25: 1973 | D25: =C25-C24 | E25: ='First-hand detail'!H24
A26: og70s | B26: O&G (1970-80s) | C26: 1973 | D26: =C26-C24 | E26: ='First-hand detail'!H25
A27: og70s | B27: O&G (1970-80s) | C27: 1974 | D27: =C27-C24 | E27: ='First-hand detail'!H25
A28: og70s | B28: O&G (1970-80s) | C28: 1974 | D28: =C28-C24 | E28: ='First-hand detail'!H26
A29: og70s | B29: O&G (1970-80s) | C29: 1975 | D29: =C29-C24 | E29: ='First-hand detail'!H26
A30: og70s | B30: O&G (1970-80s) | C30: 1975 | D30: =C30-C24 | E30: ='First-hand detail'!H27
A31: og70s | B31: O&G (1970-80s) | C31: 1976 | D31: =C31-C24 | E31: ='First-hand detail'!H27
A32: og70s | B32: O&G (1970-80s) | C32: 1976 | D32: =C32-C24 | E32: ='First-hand detail'!H28
A33: og70s | B33: O&G (1970-80s) | C33: 1977 | D33: =C33-C24 | E33: ='First-hand detail'!H28
A34: og70s | B34: O&G (1970-80s) | C34: 1977 | D34: =C34-C24 | E34: ='First-hand detail'!H29
A35: og70s | B35: O&G (1970-80s) | C35: 1978 | D35: =C35-C24 | E35: ='First-hand detail'!H29
A36: og70s | B36: O&G (1970-80s) | C36: 1978 | D36: =C36-C24 | E36: ='First-hand detail'!H30
A37: og70s | B37: O&G (1970-80s) | C37: 1979 | D37: =C37-C24 | E37: ='First-hand detail'!H30
A38: og70s | B38: O&G (1970-80s) | C38: 1979 | D38: =C38-C24 | E38: ='First-hand detail'!H31
A39: og70s | B39: O&G (1970-80s) | C39: 1980 | D39: =C39-C24 | E39: ='First-hand detail'!H31
A40: og70s | B40: O&G (1970-80s) | C40: 1980 | D40: =C40-C24 | E40: ='First-hand detail'!H32
...

Sheet Notes
A1: Source: BofA Institute, 'Can the AI buildout keep building?' (27 Aug 2026), Exhibit 2, page 2 - file 20260827_Can the AI buildout keep building (BofA Institute).pdf.
A2: Exhibit source line: BofA Global Research, BEA, and National Bureau of Economic Research.
A3: Method: the chart is vector art. Every vertex of the six stroked paths was read with PyMuPDF and converted with the chart's
A4: own gridlines (0%/1%/2%/3%) and axis labels, so values are exact to about 0.001pp (bofa-capex-cycles/extract_pdf.py).
A5: Post-1970 series sit three quarters before their period end on a quarterly grid: annual year Y fills positions Y-0.5..Y+0.25, and the
A6: hyperscaler point at position P is the four quarters ending P+0.75 (labelled 'TTM to ...').
A7: First-hand rebuild of every panel: 'First-hand vs PDF' sheet (scripts in bofa-capex-cycles/firsthand/).
