Workbook

Sheet Summary
A1: BofA Exhibit 2: Hyperscaler capex is late cycle, measured at a macro level
A2: Sector capex as % of US GDP through each cycle's speculative build phase. Values read exactly from the PDF's vector chart.
A4: Cycle | B4: Start | C4: End | D4: Start value | E4: Peak | F4: Peak year / quarter | G4: Last value | H4: Peak ÷ start | I4: Fall from peak to last | J4: Years start → peak
A5: US railroads (1900 onwards) | B5: =_xlfn.MINIFS(Annual!A2:A60,Annual!B2:B60,"<>") | C5: =_xlfn.MAXIFS(Annual!A2:A60,Annual!B2:B60,"<>") | D5: =INDEX(Annual!B2:B60,MATCH(B5,Annual!A2:A60,0)) | E5: =MAX(Annual!B2:B60) | F5: =INDEX(Annual!A2:A60,MATCH(E5,Annual!B2:B60,0)) | G5: =INDEX(Annual!B2:B60,MATCH(C5,Annual!A2:A60,0)) | H5: =E5/D5 | I5: =G5/E5-1 | J5: =F5-B5
A6: O&G (1970-80s) | B6: =_xlfn.MINIFS(Annual!A2:A60,Annual!C2:C60,"<>") | C6: =_xlfn.MAXIFS(Annual!A2:A60,Annual!C2:C60,"<>") | D6: =INDEX(Annual!C2:C60,MATCH(B6,Annual!A2:A60,0)) | E6: =MAX(Annual!C2:C60) | F6: =INDEX(Annual!A2:A60,MATCH(E6,Annual!C2:C60,0)) | G6: =INDEX(Annual!C2:C60,MATCH(C6,Annual!A2:A60,0)) | H6: =E6/D6 | I6: =G6/E6-1 | J6: =F6-B6
A7: Telecoms (1990s) | B7: =_xlfn.MINIFS(Annual!A2:A60,Annual!D2:D60,"<>") | C7: =_xlfn.MAXIFS(Annual!A2:A60,Annual!D2:D60,"<>") | D7: =INDEX(Annual!D2:D60,MATCH(B7,Annual!A2:A60,0)) | E7: =MAX(Annual!D2:D60) | F7: =INDEX(Annual!A2:A60,MATCH(E7,Annual!D2:D60,0)) | G7: =INDEX(Annual!D2:D60,MATCH(C7,Annual!A2:A60,0)) | H7: =E7/D7 | I7: =G7/E7-1 | J7: =F7-B7
A8: O&G (Shale) | B8: =_xlfn.MINIFS(Annual!A2:A60,Annual!E2:E60,"<>") | C8: =_xlfn.MAXIFS(Annual!A2:A60,Annual!E2:E60,"<>") | D8: =INDEX(Annual!E2:E60,MATCH(B8,Annual!A2:A60,0)) | E8: =MAX(Annual!E2:E60) | F8: =INDEX(Annual!A2:A60,MATCH(E8,Annual!E2:E60,0)) | G8: =INDEX(Annual!E2:E60,MATCH(C8,Annual!A2:A60,0)) | H8: =E8/D8 | I8: =G8/E8-1 | J8: =F8-B8
A9: Hyperscalers | B9: =MIN(Hyperscalers!B2:B18) | C9: =MAX(Hyperscalers!B2:B18) | D9: =INDEX(Hyperscalers!C2:C18,1) | E9: =MAX(Hyperscalers!C2:C18) | F9: =INDEX(Hyperscalers!A2:A18,MATCH(E9,Hyperscalers!C2:C18,0)) | G9: =INDEX(Hyperscalers!C2:C18,ROWS(Hyperscalers!C2:C18)) | H9: =E9/D9 | I9: =G9/E9-1 | J9: =INDEX(Hyperscalers!B2:B18,MATCH(E9,Hyperscalers!C2:C18,0))-B9
A10: Hyperscalers (lease adjusted) | B10: =MIN(Hyperscalers!B2:B18) | C10: =MAX(Hyperscalers!B2:B18) | D10: =INDEX(Hyperscalers!D2:D18,1) | E10: =MAX(Hyperscalers!D2:D18) | F10: =INDEX(Hyperscalers!A2:A18,MATCH(E10,Hyperscalers!D2:D18,0)) | G10: =INDEX(Hyperscalers!D2:D18,ROWS(Hyperscalers!D2:D18)) | H10: =E10/D10 | I10: =G10/E10-1 | J10: =INDEX(Hyperscalers!B2:B18,MATCH(E10,Hyperscalers!D2:D18,0))-B10
A12: Hyperscaler start/end are quarterly chart positions (2021.5 = mid-2021). Annual series: each year's value is drawn from mid-year Y-1 to Q1 of Y; the year column uses Y.

Sheet First-hand vs PDF
A1: Every panel rebuilt from the first-hand sources behind the footnote, compared with the PDF vector values
A3: Panel | B3: First-hand definition | C3: Points | D3: Max |diff| (pp) | E3: Mean |diff| (pp) | F3: Verdict
A4: Railroads | B4: NBER: Ulmer (1960) Table C-1 col.4 / Kuznets & Jenks (1961) R-22 col.1, R-2 col.7 (1929 prices) | C4: 22 | D4: =_xlfn.MAXIFS('First-hand detail'!$G$2:$G$79,'First-hand detail'!$A$2:$A$79,"rail") | E4: =AVERAGEIFS('First-hand detail'!$G$2:$G$79,'First-hand detail'!$A$2:$A$79,"rail") | F4: Exact
A5: O&G 1970s-80s | B5: BEA Fixed Assets: investment by industry 2110+2130+4860, all assets / GDP | C5: 15 | D5: =_xlfn.MAXIFS('First-hand detail'!$G$2:$G$79,'First-hand detail'!$A$2:$A$79,"og70s") | E5: =AVERAGEIFS('First-hand detail'!$G$2:$G$79,'First-hand detail'!$A$2:$A$79,"og70s") | F5: Exact
A6: O&G shale | B6: BEA Fixed Assets: investment by industry 2110+2130+4860, all assets / GDP | C6: 15 | D6: =_xlfn.MAXIFS('First-hand detail'!$G$2:$G$79,'First-hand detail'!$A$2:$A$79,"shale") | E6: =AVERAGEIFS('First-hand detail'!$G$2:$G$79,'First-hand detail'!$A$2:$A$79,"shale") | F6: Exact
A7: Telecoms | B7: BEA Fixed Assets: investment by industry 5130, all assets / GDP | C7: 9 | D7: =_xlfn.MAXIFS('First-hand detail'!$G$2:$G$79,'First-hand detail'!$A$2:$A$79,"telecom") | E7: =AVERAGEIFS('First-hand detail'!$G$2:$G$79,'First-hand detail'!$A$2:$A$79,"telecom") | F7: Exact
A8: Hyperscalers | B8: SEC XBRL capex MSFT+GOOGL+AMZN+META+ORCL, TTM / BEA GDP TTM | C8: 17 | D8: =_xlfn.MAXIFS('First-hand detail'!$G$2:$G$79,'First-hand detail'!$A$2:$A$79,"hyper") | E8: =AVERAGEIFS('First-hand detail'!$G$2:$G$79,'First-hand detail'!$A$2:$A$79,"hyper") | F8: Matches (RMSE 0.019pp)
A9: Hyperscalers (lease adjusted) | B9: Not reproducible from filings: the gap to reported capex is 1-2.5x the finance-lease additions companies tag; finance + principal repayments or operating-lease additions do not fit either. Treat it as BofA's own estimate. | F9: Not reproducible
A11: Dating convention found in the process: BofA plots every post-1970 point three quarters EARLY. A point drawn at position P
A12: is the four quarters ending at P+0.75: the hyperscaler point drawn at mid-2021 is TTM to 2022Q1, the last one (mid-2025)
A13: is TTM to 2026Q1. Annual year Y is drawn from Y-0.5 to Y+0.25 for the same reason.
A14: O&G is broader than drilling: BEA investment by the oil & gas extraction, support-activities-for-mining and pipeline
A15: industries, all asset types including intellectual property products. Telecoms is the broadcasting & telecoms industry, all assets.
A16: BEA vintage used here: Fixed Assets detailed investment updated 30 Sep 2026 and current NIPA GDP; identical to BofA's for these years.

Sheet First-hand detail
A1: Series | B1: Period | C1: PDF vector (% GDP) | D1: First-hand (% GDP) | E1: Difference (pp) | F1: First-hand source | G1: |Difference|
A2: rail | B2: 1899 | C2: 1.169 | D2: 1.171 | E2: =C2-D2 | F2: NBER: Ulmer (1960) Table C-1 col.4 / Kuznets & Jenks (1961) R-22 col.1, R-2 col.7 (1929 prices) | G2: =ABS(E2)
A3: rail | B3: 1900 | C3: 1.247 | D3: 1.249 | E3: =C3-D3 | F3: NBER: Ulmer (1960) Table C-1 col.4 / Kuznets & Jenks (1961) R-22 col.1, R-2 col.7 (1929 prices) | G3: =ABS(E3)
A4: rail | B4: 1901 | C4: 1.047 | D4: 1.048 | E4: =C4-D4 | F4: NBER: Ulmer (1960) Table C-1 col.4 / Kuznets & Jenks (1961) R-22 col.1, R-2 col.7 (1929 prices) | G4: =ABS(E4)
A5: rail | B5: 1902 | C5: 1.068 | D5: 1.07 | E5: =C5-D5 | F5: NBER: Ulmer (1960) Table C-1 col.4 / Kuznets & Jenks (1961) R-22 col.1, R-2 col.7 (1929 prices) | G5: =ABS(E5)
A6: rail | B6: 1903 | C6: 1.068 | D6: 1.069 | E6: =C6-D6 | F6: NBER: Ulmer (1960) Table C-1 col.4 / Kuznets & Jenks (1961) R-22 col.1, R-2 col.7 (1929 prices) | G6: =ABS(E6)
A7: rail | B7: 1904 | C7: 1.252 | D7: 1.254 | E7: =C7-D7 | F7: NBER: Ulmer (1960) Table C-1 col.4 / Kuznets & Jenks (1961) R-22 col.1, R-2 col.7 (1929 prices) | G7: =ABS(E7)
A8: rail | B8: 1905 | C8: 1.49 | D8: 1.491 | E8: =C8-D8 | F8: NBER: Ulmer (1960) Table C-1 col.4 / Kuznets & Jenks (1961) R-22 col.1, R-2 col.7 (1929 prices) | G8: =ABS(E8)
A9: rail | B9: 1906 | C9: 1.798 | D9: 1.798 | E9: =C9-D9 | F9: NBER: Ulmer (1960) Table C-1 col.4 / Kuznets & Jenks (1961) R-22 col.1, R-2 col.7 (1929 prices) | G9: =ABS(E9)
A10: rail | B10: 1907 | C10: 2.026 | D10: 2.026 | E10: =C10-D10 | F10: NBER: Ulmer (1960) Table C-1 col.4 / Kuznets & Jenks (1961) R-22 col.1, R-2 col.7 (1929 prices) | G10: =ABS(E10)
A11: rail | B11: 1908 | C11: 2.221 | D11: 2.222 | E11: =C11-D11 | F11: NBER: Ulmer (1960) Table C-1 col.4 / Kuznets & Jenks (1961) R-22 col.1, R-2 col.7 (1929 prices) | G11: =ABS(E11)
A12: rail | B12: 1909 | C12: 2.115 | D12: 2.115 | E12: =C12-D12 | F12: NBER: Ulmer (1960) Table C-1 col.4 / Kuznets & Jenks (1961) R-22 col.1, R-2 col.7 (1929 prices) | G12: =ABS(E12)
A13: rail | B13: 1910 | C13: 2.303 | D13: 2.303 | E13: =C13-D13 | F13: NBER: Ulmer (1960) Table C-1 col.4 / Kuznets & Jenks (1961) R-22 col.1, R-2 col.7 (1929 prices) | G13: =ABS(E13)
... A79: hyper | B79: TTM to 2026Q1 | C79: 1.536 | D79: 1.541 | E79: =C79-D79 | F79: SEC XBRL capex MSFT+GOOGL+AMZN+META+ORCL, TTM / BEA GDP TTM | G79: =ABS(E79)

Sheet Chart points
A1: Series | B1: Label | C1: Chart position (year) | D1: Years since cycle start | E1: % of US GDP | F1: Year (annual series) | G1: Years since start (value)
A2: rail | B2: US railroads (1900 onwards) | C2: 1899 | D2: =C2-C2 | E2: 1.169 | F2: 1899 | G2: 0
A3: rail | B3: US railroads (1900 onwards) | C3: 1900 | D3: =C3-C2 | E3: 1.247 | F3: 1900 | G3: 1
A4: rail | B4: US railroads (1900 onwards) | C4: 1901 | D4: =C4-C2 | E4: 1.047 | F4: 1901 | G4: 2
A5: rail | B5: US railroads (1900 onwards) | C5: 1902 | D5: =C5-C2 | E5: 1.068 | F5: 1902 | G5: 3
A6: rail | B6: US railroads (1900 onwards) | C6: 1903 | D6: =C6-C2 | E6: 1.068 | F6: 1903 | G6: 4
A7: rail | B7: US railroads (1900 onwards) | C7: 1904 | D7: =C7-C2 | E7: 1.252 | F7: 1904 | G7: 5
A8: rail | B8: US railroads (1900 onwards) | C8: 1905 | D8: =C8-C2 | E8: 1.49 | F8: 1905 | G8: 6
A9: rail | B9: US railroads (1900 onwards) | C9: 1906 | D9: =C9-C2 | E9: 1.798 | F9: 1906 | G9: 7
A10: rail | B10: US railroads (1900 onwards) | C10: 1907 | D10: =C10-C2 | E10: 2.026 | F10: 1907 | G10: 8
A11: rail | B11: US railroads (1900 onwards) | C11: 1908 | D11: =C11-C2 | E11: 2.221 | F11: 1908 | G11: 9
A12: rail | B12: US railroads (1900 onwards) | C12: 1909 | D12: =C12-C2 | E12: 2.115 | F12: 1909 | G12: 10
A13: rail | B13: US railroads (1900 onwards) | C13: 1910 | D13: =C13-C2 | E13: 2.303 | F13: 1910 | G13: 11
A14: rail | B14: US railroads (1900 onwards) | C14: 1911 | D14: =C14-C2 | E14: 2.117 | F14: 1911 | G14: 12
A15: rail | B15: US railroads (1900 onwards) | C15: 1912 | D15: =C15-C2 | E15: 1.998 | F15: 1912 | G15: 13
A16: rail | B16: US railroads (1900 onwards) | C16: 1913 | D16: =C16-C2 | E16: 1.979 | F16: 1913 | G16: 14
A17: rail | B17: US railroads (1900 onwards) | C17: 1914 | D17: =C17-C2 | E17: 1.418 | F17: 1914 | G17: 15
A18: rail | B18: US railroads (1900 onwards) | C18: 1915 | D18: =C18-C2 | E18: 0.79 | F18: 1915 | G18: 16
A19: rail | B19: US railroads (1900 onwards) | C19: 1916 | D19: =C19-C2 | E19: 0.816 | F19: 1916 | G19: 17
A20: rail | B20: US railroads (1900 onwards) | C20: 1917 | D20: =C20-C2 | E20: 1.013 | F20: 1917 | G20: 18
A21: rail | B21: US railroads (1900 onwards) | C21: 1918 | D21: =C21-C2 | E21: 0.78 | F21: 1918 | G21: 19
A22: rail | B22: US railroads (1900 onwards) | C22: 1919 | D22: =C22-C2 | E22: 0.508 | F22: 1919 | G22: 20
A23: rail | B23: US railroads (1900 onwards) | C23: 1920 | D23: =C23-C2 | E23: 0.726 | F23: 1920 | G23: 21
A24: og70s | B24: O&G (1970-80s) | C24: 1972 | D24: =C24-C24 | E24: 0.379 | F24: 1972 | G24: 0
A25: og70s | B25: O&G (1970-80s) | C25: 1972.25 | D25: =C25-C24 | E25: 0.379 | F25: 1972 | G25: 0.25
A26: og70s | B26: O&G (1970-80s) | C26: 1972.5 | D26: =C26-C24 | E26: 0.391 | F26: 1973 | G26: 0.5
A27: og70s | B27: O&G (1970-80s) | C27: 1972.75 | D27: =C27-C24 | E27: 0.391 | F27: 1973 | G27: 0.75
A28: og70s | B28: O&G (1970-80s) | C28: 1973 | D28: =C28-C24 | E28: 0.391 | F28: 1973 | G28: 1
A29: og70s | B29: O&G (1970-80s) | C29: 1973.25 | D29: =C29-C24 | E29: 0.391 | F29: 1973 | G29: 1.25
A30: og70s | B30: O&G (1970-80s) | C30: 1973.5 | D30: =C30-C24 | E30: 0.495 | F30: 1974 | G30: 1.5
A31: og70s | B31: O&G (1970-80s) | C31: 1973.75 | D31: =C31-C24 | E31: 0.495 | F31: 1974 | G31: 1.75
A32: og70s | B32: O&G (1970-80s) | C32: 1974 | D32: =C32-C24 | E32: 0.495 | F32: 1974 | G32: 2
A33: og70s | B33: O&G (1970-80s) | C33: 1974.25 | D33: =C33-C24 | E33: 0.495 | F33: 1974 | G33: 2.25
A34: og70s | B34: O&G (1970-80s) | C34: 1974.5 | D34: =C34-C24 | E34: 0.665 | F34: 1975 | G34: 2.5
A35: og70s | B35: O&G (1970-80s) | C35: 1974.75 | D35: =C35-C24 | E35: 0.665 | F35: 1975 | G35: 2.75
A36: og70s | B36: O&G (1970-80s) | C36: 1975 | D36: =C36-C24 | E36: 0.665 | F36: 1975 | G36: 3
A37: og70s | B37: O&G (1970-80s) | C37: 1975.25 | D37: =C37-C24 | E37: 0.665 | F37: 1975 | G37: 3.25
A38: og70s | B38: O&G (1970-80s) | C38: 1975.5 | D38: =C38-C24 | E38: 0.7 | F38: 1976 | G38: 3.5
A39: og70s | B39: O&G (1970-80s) | C39: 1975.75 | D39: =C39-C24 | E39: 0.7 | F39: 1976 | G39: 3.75
A40: og70s | B40: O&G (1970-80s) | C40: 1976 | D40: =C40-C24 | E40: 0.7 | F40: 1976 | G40: 4
...

Sheet Annual
A1: Year | B1: US railroads (1900 onwards) | C1: O&G (1970-80s) | D1: Telecoms (1990s) | E1: O&G (Shale)
A2: 1899 | B2: 1.169
A3: 1900 | B3: 1.247
A4: 1901 | B4: 1.047
A5: 1902 | B5: 1.068
A6: 1903 | B6: 1.068
A7: 1904 | B7: 1.252
A8: 1905 | B8: 1.49
A9: 1906 | B9: 1.798
A10: 1907 | B10: 2.026
A11: 1908 | B11: 2.221
A12: 1909 | B12: 2.115
A13: 1910 | B13: 2.303
... A23: 1920 | B23: 0.726
A24: 1972 | C24: 0.379
A25: 1973 | C25: 0.391
A26: 1974 | C26: 0.495
A27: 1975 | C27: 0.665
A28: 1976 | C28: 0.7
A29: 1977 | C29: 0.722
A30: 1978 | C30: 0.909
A31: 1979 | C31: 1.064
A32: 1980 | C32: 1.425
A33: 1981 | C33: 1.972
A34: 1982 | C34: 1.891
A35: 1983 | C35: 1.182
... A38: 1986 | C38: 0.516
A39: 1995 | D39: 1.054
A40: 1996 | D40: 1.083
A41: 1997 | D41: 1.098
A42: 1998 | D42: 1.135
A43: 1999 | D43: 1.285
A44: 2000 | D44: 1.54
A45: 2001 | D45: 1.337
A46: 2002 | D46: 0.91 | E46: 0.395
A47: 2003 | D47: 0.789 | E47: 0.468
A48: 2004 | E48: 0.505
A49: 2005 | E49: 0.653
A50: 2006 | E50: 0.866
A51: 2007 | E51: 0.95
...

Sheet Hyperscalers
A1: Trailing 4 quarters to | B1: Position (year) | C1: Hyperscalers | D1: Hyperscalers (lease adjusted) | E1: Lease adjustment (pp)
A2: TTM to 2022Q1 | B2: 2021.5 | C2: 0.537 | D2: 0.616 | E2: =D2-C2
A3: TTM to 2022Q2 | B3: 2021.75 | C3: 0.564 | D3: 0.637 | E3: =D3-C3
A4: TTM to 2022Q3 | B4: 2022 | C4: 0.595 | D4: 0.64 | E4: =D4-C4
A5: TTM to 2022Q4 | B5: 2022.25 | C5: 0.611 | D5: 0.655 | E5: =D5-C5
A6: TTM to 2023Q1 | B6: 2022.5 | C6: 0.569 | D6: 0.627 | E6: =D6-C6
A7: TTM to 2023Q2 | B7: 2022.75 | C7: 0.555 | D7: 0.614 | E7: =D7-C7
A8: TTM to 2023Q3 | B8: 2023 | C8: 0.542 | D8: 0.592 | E8: =D8-C8
A9: TTM to 2023Q4 | B9: 2023.25 | C9: 0.551 | D9: 0.595 | E9: =D9-C9
A10: TTM to 2024Q1 | B10: 2023.5 | C10: 0.562 | D10: 0.596 | E10: =D10-C10
A11: TTM to 2024Q2 | B11: 2023.75 | C11: 0.63 | D11: 0.686 | E11: =D11-C11
A12: TTM to 2024Q3 | B12: 2024 | C12: 0.715 | D12: 0.78 | E12: =D12-C12
A13: TTM to 2024Q4 | B13: 2024.25 | C13: 0.829 | D13: 0.896 | E13: =D13-C13
... A18: TTM to 2026Q1 | B18: 2025.5 | C18: 1.536 | D18: 1.702 | E18: =D18-C18

Sheet Hyperscalers first-hand
A1: TTM to | B1: MSFT | C1: GOOGL | D1: AMZN | E1: META | F1: ORCL | G1: Capex, 5 names ($bn) | H1: BEA GDP, TTM ($bn) | I1: % of US GDP
A2: 2020Q4 | B2: 17.6 | C2: 22.3 | D2: 40.1 | E2: 15.2 | F2: 1.8 | G2: =SUM(B2:F2) | H2: 21375 | I2: =G2/H2*100
A3: 2021Q1 | B3: 18.9 | C3: 22.2 | D3: 45.4 | E3: 15.9 | F3: 1.9 | G3: =SUM(B3:F3) | H3: 21614 | I3: =G3/H3*100
A4: 2021Q2 | B4: 20.6 | C4: 22.3 | D4: 52.3 | E4: 17.3 | F4: 2.1 | G4: =SUM(B4:F4) | H4: 22488 | I4: =G4/H4*100
A5: 2021Q3 | B5: 21.5 | C5: 23.7 | D5: 56.9 | E5: 18 | F5: 2.8 | G5: =SUM(B5:F5) | H5: 23062 | I5: =G5/H5*100
A6: 2021Q4 | B6: 23.2 | C6: 24.6 | D6: 61.1 | E6: 18.7 | F6: 3.1 | G6: =SUM(B6:F6) | H6: 23746 | I6: =G6/H6*100
A7: 2022Q1 | B7: 23.5 | C7: 28.5 | D7: 63.9 | E7: 19.8 | F7: 3.8 | G7: =SUM(B7:F7) | H7: 24385 | I7: =G7/H7*100
A8: 2022Q2 | B8: 23.9 | C8: 29.8 | D8: 65.4 | E8: 22.8 | F8: 4.5 | G8: =SUM(B8:F8) | H8: 24988 | I8: =G8/H8*100
A9: 2022Q3 | B9: 24.4 | C9: 30.3 | D9: 66 | E9: 27.8 | F9: 5.2 | G9: =SUM(B9:F9) | H9: 25572 | I9: =G9/H9*100
A10: 2022Q4 | B10: 24.8 | C10: 31.5 | D10: 63.6 | E10: 31.2 | F10: 6.7 | G10: =SUM(B10:F10) | H10: 26060 | I10: =G10/H10*100
A11: 2023Q1 | B11: 26 | C11: 28 | D11: 62.9 | E11: 32.6 | F11: 8.2 | G11: =SUM(B11:F11) | H11: 26555 | I11: =G11/H11*100
A12: 2023Q2 | B12: 28.1 | C12: 28 | D12: 58.6 | E12: 31.1 | F12: 8.7 | G12: =SUM(B12:F12) | H12: 26971 | I12: =G12/H12*100
A13: 2023Q3 | B13: 31.7 | C13: 28.8 | D13: 54.7 | E13: 28.3 | F13: 8.3 | G13: =SUM(B13:F13) | H13: 27403 | I13: =G13/H13*100
... A24: 2026Q2 | B24: 115.9 | C24: 132.4 | D24: 173 | E24: 89.3 | F24: 55.7 | G24: =SUM(B24:F24) | H24: 31778 | I24: =G24/H24*100
A26: SEC XBRL purchases of property & equipment (Amazon: PaymentsToAcquireProductiveAssets), discrete quarters from YTD filings; Oracle's Aug/Nov/Feb/May quarters go in the calendar quarter they end in; GDP = BEA NIPA A191RC. Runs past the exhibit's last point (TTM to 2026Q1).

Sheet Notes
A1: Source: BofA Institute, 'Can the AI buildout keep building?' (27 Aug 2026), Exhibit 2, page 2 - file 20260827_Can the AI buildout keep building (BofA Institute).pdf.
A2: Exhibit source line: BofA Global Research, BEA, and National Bureau of Economic Research.
A3: Method: the chart is vector art. Every vertex of the six stroked paths was read with PyMuPDF and converted with the chart's
A4: own gridlines (0%/1%/2%/3%) and axis labels, so values are exact to about 0.001pp (bofa-capex-cycles/extract_pdf.py).
A5: Post-1970 series are plotted three quarters early on a quarterly grid: annual year Y fills positions Y-0.5..Y+0.25, and the
A6: hyperscaler point at position P is the four quarters ending P+0.75 (labelled 'TTM to ...').
A7: First-hand rebuild of every panel: 'First-hand vs PDF' sheet (scripts in bofa-capex-cycles/firsthand/).
