Workbook

Sheet Summary
A1: Global population 2025 — by region, income level and age (millions)
A2: Source: World Bank WDI (population by 5-year age band & sex, updated 2026-07-01; income groups = World Bank FY2027 classification, regions = World Bank). All cells are SUMIFS on the Countries sheet.
A4: 1. By region
A5: Region | B5: 0-14 | C5: 15-24 | D5: 25-34 | E5: 35-44 | F5: 45-54 | G5: 55-64 | H5: 65+ | I5: Total | J5: % of world | K5: % 0-14 | L5: % 15-24 | M5: % 25-34 | N5: % 35-44 | O5: % 45-54 | P5: % 55-64 | Q5: % 65+ | R5: Countries
A6: East Asia & Pacific | B6: =SUMIFS(Countries!$X$5:$X$222,Countries!$C$5:$C$222,"East Asia & Pacific")/1000000 | C6: =SUMIFS(Countries!$Y$5:$Y$222,Countries!$C$5:$C$222,"East Asia & Pacific")/1000000 | D6: =SUMIFS(Countries!$Z$5:$Z$222,Countries!$C$5:$C$222,"East Asia & Pacific")/1000000 | E6: =SUMIFS(Countries!$AA$5:$AA$222,Countries!$C$5:$C$222,"East Asia & Pacific")/1000000 | F6: =SUMIFS(Countries!$AB$5:$AB$222,Countries!$C$5:$C$222,"East Asia & Pacific")/1000000 | G6: =SUMIFS(Countries!$AC$5:$AC$222,Countries!$C$5:$C$222,"East Asia & Pacific")/1000000 | H6: =SUMIFS(Countries!$AD$5:$AD$222,Countries!$C$5:$C$222,"East Asia & Pacific")/1000000 | I6: =SUM(B6:H6) | J6: =I6/I$13 | K6: =IF($I6>0,B6/$I6,0) | L6: =IF($I6>0,C6/$I6,0) | M6: =IF($I6>0,D6/$I6,0) | N6: =IF($I6>0,E6/$I6,0) | O6: =IF($I6>0,F6/$I6,0) | P6: =IF($I6>0,G6/$I6,0) | Q6: =IF($I6>0,H6/$I6,0) | R6: =COUNTIFS(Countries!$C$5:$C$222,"East Asia & Pacific")
A7: South Asia | B7: =SUMIFS(Countries!$X$5:$X$222,Countries!$C$5:$C$222,"South Asia")/1000000 | C7: =SUMIFS(Countries!$Y$5:$Y$222,Countries!$C$5:$C$222,"South Asia")/1000000 | D7: =SUMIFS(Countries!$Z$5:$Z$222,Countries!$C$5:$C$222,"South Asia")/1000000 | E7: =SUMIFS(Countries!$AA$5:$AA$222,Countries!$C$5:$C$222,"South Asia")/1000000 | F7: =SUMIFS(Countries!$AB$5:$AB$222,Countries!$C$5:$C$222,"South Asia")/1000000 | G7: =SUMIFS(Countries!$AC$5:$AC$222,Countries!$C$5:$C$222,"South Asia")/1000000 | H7: =SUMIFS(Countries!$AD$5:$AD$222,Countries!$C$5:$C$222,"South Asia")/1000000 | I7: =SUM(B7:H7) | J7: =I7/I$13 | K7: =IF($I7>0,B7/$I7,0) | L7: =IF($I7>0,C7/$I7,0) | M7: =IF($I7>0,D7/$I7,0) | N7: =IF($I7>0,E7/$I7,0) | O7: =IF($I7>0,F7/$I7,0) | P7: =IF($I7>0,G7/$I7,0) | Q7: =IF($I7>0,H7/$I7,0) | R7: =COUNTIFS(Countries!$C$5:$C$222,"South Asia")
A8: Sub-Saharan Africa | B8: =SUMIFS(Countries!$X$5:$X$222,Countries!$C$5:$C$222,"Sub-Saharan Africa")/1000000 | C8: =SUMIFS(Countries!$Y$5:$Y$222,Countries!$C$5:$C$222,"Sub-Saharan Africa")/1000000 | D8: =SUMIFS(Countries!$Z$5:$Z$222,Countries!$C$5:$C$222,"Sub-Saharan Africa")/1000000 | E8: =SUMIFS(Countries!$AA$5:$AA$222,Countries!$C$5:$C$222,"Sub-Saharan Africa")/1000000 | F8: =SUMIFS(Countries!$AB$5:$AB$222,Countries!$C$5:$C$222,"Sub-Saharan Africa")/1000000 | G8: =SUMIFS(Countries!$AC$5:$AC$222,Countries!$C$5:$C$222,"Sub-Saharan Africa")/1000000 | H8: =SUMIFS(Countries!$AD$5:$AD$222,Countries!$C$5:$C$222,"Sub-Saharan Africa")/1000000 | I8: =SUM(B8:H8) | J8: =I8/I$13 | K8: =IF($I8>0,B8/$I8,0) | L8: =IF($I8>0,C8/$I8,0) | M8: =IF($I8>0,D8/$I8,0) | N8: =IF($I8>0,E8/$I8,0) | O8: =IF($I8>0,F8/$I8,0) | P8: =IF($I8>0,G8/$I8,0) | Q8: =IF($I8>0,H8/$I8,0) | R8: =COUNTIFS(Countries!$C$5:$C$222,"Sub-Saharan Africa")
A9: Europe & Central Asia | B9: =SUMIFS(Countries!$X$5:$X$222,Countries!$C$5:$C$222,"Europe & Central Asia")/1000000 | C9: =SUMIFS(Countries!$Y$5:$Y$222,Countries!$C$5:$C$222,"Europe & Central Asia")/1000000 | D9: =SUMIFS(Countries!$Z$5:$Z$222,Countries!$C$5:$C$222,"Europe & Central Asia")/1000000 | E9: =SUMIFS(Countries!$AA$5:$AA$222,Countries!$C$5:$C$222,"Europe & Central Asia")/1000000 | F9: =SUMIFS(Countries!$AB$5:$AB$222,Countries!$C$5:$C$222,"Europe & Central Asia")/1000000 | G9: =SUMIFS(Countries!$AC$5:$AC$222,Countries!$C$5:$C$222,"Europe & Central Asia")/1000000 | H9: =SUMIFS(Countries!$AD$5:$AD$222,Countries!$C$5:$C$222,"Europe & Central Asia")/1000000 | I9: =SUM(B9:H9) | J9: =I9/I$13 | K9: =IF($I9>0,B9/$I9,0) | L9: =IF($I9>0,C9/$I9,0) | M9: =IF($I9>0,D9/$I9,0) | N9: =IF($I9>0,E9/$I9,0) | O9: =IF($I9>0,F9/$I9,0) | P9: =IF($I9>0,G9/$I9,0) | Q9: =IF($I9>0,H9/$I9,0) | R9: =COUNTIFS(Countries!$C$5:$C$222,"Europe & Central Asia")
A10: Middle East, North Africa, Afghanistan & Pakistan | B10: =SUMIFS(Countries!$X$5:$X$222,Countries!$C$5:$C$222,"Middle East, North Africa, Afghanistan & Pakistan")/1000000 | C10: =SUMIFS(Countries!$Y$5:$Y$222,Countries!$C$5:$C$222,"Middle East, North Africa, Afghanistan & Pakistan")/1000000 | D10: =SUMIFS(Countries!$Z$5:$Z$222,Countries!$C$5:$C$222,"Middle East, North Africa, Afghanistan & Pakistan")/1000000 | E10: =SUMIFS(Countries!$AA$5:$AA$222,Countries!$C$5:$C$222,"Middle East, North Africa, Afghanistan & Pakistan")/1000000 | F10: =SUMIFS(Countries!$AB$5:$AB$222,Countries!$C$5:$C$222,"Middle East, North Africa, Afghanistan & Pakistan")/1000000 | G10: =SUMIFS(Countries!$AC$5:$AC$222,Countries!$C$5:$C$222,"Middle East, North Africa, Afghanistan & Pakistan")/1000000 | H10: =SUMIFS(Countries!$AD$5:$AD$222,Countries!$C$5:$C$222,"Middle East, North Africa, Afghanistan & Pakistan")/1000000 | I10: =SUM(B10:H10) | J10: =I10/I$13 | K10: =IF($I10>0,B10/$I10,0) | L10: =IF($I10>0,C10/$I10,0) | M10: =IF($I10>0,D10/$I10,0) | N10: =IF($I10>0,E10/$I10,0) | O10: =IF($I10>0,F10/$I10,0) | P10: =IF($I10>0,G10/$I10,0) | Q10: =IF($I10>0,H10/$I10,0) | R10: =COUNTIFS(Countries!$C$5:$C$222,"Middle East, North Africa, Afghanistan & Pakistan")
A11: Latin America & Caribbean | B11: =SUMIFS(Countries!$X$5:$X$222,Countries!$C$5:$C$222,"Latin America & Caribbean")/1000000 | C11: =SUMIFS(Countries!$Y$5:$Y$222,Countries!$C$5:$C$222,"Latin America & Caribbean")/1000000 | D11: =SUMIFS(Countries!$Z$5:$Z$222,Countries!$C$5:$C$222,"Latin America & Caribbean")/1000000 | E11: =SUMIFS(Countries!$AA$5:$AA$222,Countries!$C$5:$C$222,"Latin America & Caribbean")/1000000 | F11: =SUMIFS(Countries!$AB$5:$AB$222,Countries!$C$5:$C$222,"Latin America & Caribbean")/1000000 | G11: =SUMIFS(Countries!$AC$5:$AC$222,Countries!$C$5:$C$222,"Latin America & Caribbean")/1000000 | H11: =SUMIFS(Countries!$AD$5:$AD$222,Countries!$C$5:$C$222,"Latin America & Caribbean")/1000000 | I11: =SUM(B11:H11) | J11: =I11/I$13 | K11: =IF($I11>0,B11/$I11,0) | L11: =IF($I11>0,C11/$I11,0) | M11: =IF($I11>0,D11/$I11,0) | N11: =IF($I11>0,E11/$I11,0) | O11: =IF($I11>0,F11/$I11,0) | P11: =IF($I11>0,G11/$I11,0) | Q11: =IF($I11>0,H11/$I11,0) | R11: =COUNTIFS(Countries!$C$5:$C$222,"Latin America & Caribbean")
A12: North America | B12: =SUMIFS(Countries!$X$5:$X$222,Countries!$C$5:$C$222,"North America")/1000000 | C12: =SUMIFS(Countries!$Y$5:$Y$222,Countries!$C$5:$C$222,"North America")/1000000 | D12: =SUMIFS(Countries!$Z$5:$Z$222,Countries!$C$5:$C$222,"North America")/1000000 | E12: =SUMIFS(Countries!$AA$5:$AA$222,Countries!$C$5:$C$222,"North America")/1000000 | F12: =SUMIFS(Countries!$AB$5:$AB$222,Countries!$C$5:$C$222,"North America")/1000000 | G12: =SUMIFS(Countries!$AC$5:$AC$222,Countries!$C$5:$C$222,"North America")/1000000 | H12: =SUMIFS(Countries!$AD$5:$AD$222,Countries!$C$5:$C$222,"North America")/1000000 | I12: =SUM(B12:H12) | J12: =I12/I$13 | K12: =IF($I12>0,B12/$I12,0) | L12: =IF($I12>0,C12/$I12,0) | M12: =IF($I12>0,D12/$I12,0) | N12: =IF($I12>0,E12/$I12,0) | O12: =IF($I12>0,F12/$I12,0) | P12: =IF($I12>0,G12/$I12,0) | Q12: =IF($I12>0,H12/$I12,0) | R12: =COUNTIFS(Countries!$C$5:$C$222,"North America")
A13: World | B13: =SUM(B6:B12) | C13: =SUM(C6:C12) | D13: =SUM(D6:D12) | E13: =SUM(E6:E12) | F13: =SUM(F6:F12) | G13: =SUM(G6:G12) | H13: =SUM(H6:H12) | I13: =SUM(I6:I12) | J13: =SUM(J6:J12) | K13: =B13/$I13 | L13: =C13/$I13 | M13: =D13/$I13 | N13: =E13/$I13 | O13: =F13/$I13 | P13: =G13/$I13 | Q13: =H13/$I13 | R13: =SUM(R6:R12)
A15: 2. By income level
A16: Income level | B16: 0-14 | C16: 15-24 | D16: 25-34 | E16: 35-44 | F16: 45-54 | G16: 55-64 | H16: 65+ | I16: Total | J16: % of world | K16: % 0-14 | L16: % 15-24 | M16: % 25-34 | N16: % 35-44 | O16: % 45-54 | P16: % 55-64 | Q16: % 65+ | R16: Countries
A17: High income | B17: =SUMIFS(Countries!$X$5:$X$222,Countries!$D$5:$D$222,"High income")/1000000 | C17: =SUMIFS(Countries!$Y$5:$Y$222,Countries!$D$5:$D$222,"High income")/1000000 | D17: =SUMIFS(Countries!$Z$5:$Z$222,Countries!$D$5:$D$222,"High income")/1000000 | E17: =SUMIFS(Countries!$AA$5:$AA$222,Countries!$D$5:$D$222,"High income")/1000000 | F17: =SUMIFS(Countries!$AB$5:$AB$222,Countries!$D$5:$D$222,"High income")/1000000 | G17: =SUMIFS(Countries!$AC$5:$AC$222,Countries!$D$5:$D$222,"High income")/1000000 | H17: =SUMIFS(Countries!$AD$5:$AD$222,Countries!$D$5:$D$222,"High income")/1000000 | I17: =SUM(B17:H17) | J17: =I17/I$21 | K17: =IF($I17>0,B17/$I17,0) | L17: =IF($I17>0,C17/$I17,0) | M17: =IF($I17>0,D17/$I17,0) | N17: =IF($I17>0,E17/$I17,0) | O17: =IF($I17>0,F17/$I17,0) | P17: =IF($I17>0,G17/$I17,0) | Q17: =IF($I17>0,H17/$I17,0) | R17: =COUNTIFS(Countries!$D$5:$D$222,"High income")
A18: Upper middle income | B18: =SUMIFS(Countries!$X$5:$X$222,Countries!$D$5:$D$222,"Upper middle income")/1000000 | C18: =SUMIFS(Countries!$Y$5:$Y$222,Countries!$D$5:$D$222,"Upper middle income")/1000000 | D18: =SUMIFS(Countries!$Z$5:$Z$222,Countries!$D$5:$D$222,"Upper middle income")/1000000 | E18: =SUMIFS(Countries!$AA$5:$AA$222,Countries!$D$5:$D$222,"Upper middle income")/1000000 | F18: =SUMIFS(Countries!$AB$5:$AB$222,Countries!$D$5:$D$222,"Upper middle income")/1000000 | G18: =SUMIFS(Countries!$AC$5:$AC$222,Countries!$D$5:$D$222,"Upper middle income")/1000000 | H18: =SUMIFS(Countries!$AD$5:$AD$222,Countries!$D$5:$D$222,"Upper middle income")/1000000 | I18: =SUM(B18:H18) | J18: =I18/I$21 | K18: =IF($I18>0,B18/$I18,0) | L18: =IF($I18>0,C18/$I18,0) | M18: =IF($I18>0,D18/$I18,0) | N18: =IF($I18>0,E18/$I18,0) | O18: =IF($I18>0,F18/$I18,0) | P18: =IF($I18>0,G18/$I18,0) | Q18: =IF($I18>0,H18/$I18,0) | R18: =COUNTIFS(Countries!$D$5:$D$222,"Upper middle income")
A19: Lower middle income | B19: =SUMIFS(Countries!$X$5:$X$222,Countries!$D$5:$D$222,"Lower middle income")/1000000 | C19: =SUMIFS(Countries!$Y$5:$Y$222,Countries!$D$5:$D$222,"Lower middle income")/1000000 | D19: =SUMIFS(Countries!$Z$5:$Z$222,Countries!$D$5:$D$222,"Lower middle income")/1000000 | E19: =SUMIFS(Countries!$AA$5:$AA$222,Countries!$D$5:$D$222,"Lower middle income")/1000000 | F19: =SUMIFS(Countries!$AB$5:$AB$222,Countries!$D$5:$D$222,"Lower middle income")/1000000 | G19: =SUMIFS(Countries!$AC$5:$AC$222,Countries!$D$5:$D$222,"Lower middle income")/1000000 | H19: =SUMIFS(Countries!$AD$5:$AD$222,Countries!$D$5:$D$222,"Lower middle income")/1000000 | I19: =SUM(B19:H19) | J19: =I19/I$21 | K19: =IF($I19>0,B19/$I19,0) | L19: =IF($I19>0,C19/$I19,0) | M19: =IF($I19>0,D19/$I19,0) | N19: =IF($I19>0,E19/$I19,0) | O19: =IF($I19>0,F19/$I19,0) | P19: =IF($I19>0,G19/$I19,0) | Q19: =IF($I19>0,H19/$I19,0) | R19: =COUNTIFS(Countries!$D$5:$D$222,"Lower middle income")
A20: Low income | B20: =SUMIFS(Countries!$X$5:$X$222,Countries!$D$5:$D$222,"Low income")/1000000 | C20: =SUMIFS(Countries!$Y$5:$Y$222,Countries!$D$5:$D$222,"Low income")/1000000 | D20: =SUMIFS(Countries!$Z$5:$Z$222,Countries!$D$5:$D$222,"Low income")/1000000 | E20: =SUMIFS(Countries!$AA$5:$AA$222,Countries!$D$5:$D$222,"Low income")/1000000 | F20: =SUMIFS(Countries!$AB$5:$AB$222,Countries!$D$5:$D$222,"Low income")/1000000 | G20: =SUMIFS(Countries!$AC$5:$AC$222,Countries!$D$5:$D$222,"Low income")/1000000 | H20: =SUMIFS(Countries!$AD$5:$AD$222,Countries!$D$5:$D$222,"Low income")/1000000 | I20: =SUM(B20:H20) | J20: =I20/I$21 | K20: =IF($I20>0,B20/$I20,0) | L20: =IF($I20>0,C20/$I20,0) | M20: =IF($I20>0,D20/$I20,0) | N20: =IF($I20>0,E20/$I20,0) | O20: =IF($I20>0,F20/$I20,0) | P20: =IF($I20>0,G20/$I20,0) | Q20: =IF($I20>0,H20/$I20,0) | R20: =COUNTIFS(Countries!$D$5:$D$222,"Low income")
A21: World | B21: =SUM(B17:B20) | C21: =SUM(C17:C20) | D21: =SUM(D17:D20) | E21: =SUM(E17:E20) | F21: =SUM(F17:F20) | G21: =SUM(G17:G20) | H21: =SUM(H17:H20) | I21: =SUM(I17:I20) | J21: =SUM(J17:J20) | K21: =B21/$I21 | L21: =C21/$I21 | M21: =D21/$I21 | N21: =E21/$I21 | O21: =F21/$I21 | P21: =G21/$I21 | Q21: =H21/$I21 | R21: =SUM(R17:R20)
A23: 3. Region x income level (millions)
A24: Region | B24: High income | C24: Upper middle income | D24: Lower middle income | E24: Low income | F24: Total | G24: % High income | H24: % Upper middle income | I24: % Lower middle income | J24: % Low income
A25: East Asia & Pacific | B25: =SUMIFS(Countries!$AE$5:$AE$222,Countries!$C$5:$C$222,"East Asia & Pacific",Countries!$D$5:$D$222,"High income")/1000000 | C25: =SUMIFS(Countries!$AE$5:$AE$222,Countries!$C$5:$C$222,"East Asia & Pacific",Countries!$D$5:$D$222,"Upper middle income")/1000000 | D25: =SUMIFS(Countries!$AE$5:$AE$222,Countries!$C$5:$C$222,"East Asia & Pacific",Countries!$D$5:$D$222,"Lower middle income")/1000000 | E25: =SUMIFS(Countries!$AE$5:$AE$222,Countries!$C$5:$C$222,"East Asia & Pacific",Countries!$D$5:$D$222,"Low income")/1000000 | F25: =SUM(B25:E25) | G25: =IF($F25>0,B25/$F25,0) | H25: =IF($F25>0,C25/$F25,0) | I25: =IF($F25>0,D25/$F25,0) | J25: =IF($F25>0,E25/$F25,0)
A26: South Asia | B26: =SUMIFS(Countries!$AE$5:$AE$222,Countries!$C$5:$C$222,"South Asia",Countries!$D$5:$D$222,"High income")/1000000 | C26: =SUMIFS(Countries!$AE$5:$AE$222,Countries!$C$5:$C$222,"South Asia",Countries!$D$5:$D$222,"Upper middle income")/1000000 | D26: =SUMIFS(Countries!$AE$5:$AE$222,Countries!$C$5:$C$222,"South Asia",Countries!$D$5:$D$222,"Lower middle income")/1000000 | E26: =SUMIFS(Countries!$AE$5:$AE$222,Countries!$C$5:$C$222,"South Asia",Countries!$D$5:$D$222,"Low income")/1000000 | F26: =SUM(B26:E26) | G26: =IF($F26>0,B26/$F26,0) | H26: =IF($F26>0,C26/$F26,0) | I26: =IF($F26>0,D26/$F26,0) | J26: =IF($F26>0,E26/$F26,0)
A27: Sub-Saharan Africa | B27: =SUMIFS(Countries!$AE$5:$AE$222,Countries!$C$5:$C$222,"Sub-Saharan Africa",Countries!$D$5:$D$222,"High income")/1000000 | C27: =SUMIFS(Countries!$AE$5:$AE$222,Countries!$C$5:$C$222,"Sub-Saharan Africa",Countries!$D$5:$D$222,"Upper middle income")/1000000 | D27: =SUMIFS(Countries!$AE$5:$AE$222,Countries!$C$5:$C$222,"Sub-Saharan Africa",Countries!$D$5:$D$222,"Lower middle income")/1000000 | E27: =SUMIFS(Countries!$AE$5:$AE$222,Countries!$C$5:$C$222,"Sub-Saharan Africa",Countries!$D$5:$D$222,"Low income")/1000000 | F27: =SUM(B27:E27) | G27: =IF($F27>0,B27/$F27,0) | H27: =IF($F27>0,C27/$F27,0) | I27: =IF($F27>0,D27/$F27,0) | J27: =IF($F27>0,E27/$F27,0)
A28: Europe & Central Asia | B28: =SUMIFS(Countries!$AE$5:$AE$222,Countries!$C$5:$C$222,"Europe & Central Asia",Countries!$D$5:$D$222,"High income")/1000000 | C28: =SUMIFS(Countries!$AE$5:$AE$222,Countries!$C$5:$C$222,"Europe & Central Asia",Countries!$D$5:$D$222,"Upper middle income")/1000000 | D28: =SUMIFS(Countries!$AE$5:$AE$222,Countries!$C$5:$C$222,"Europe & Central Asia",Countries!$D$5:$D$222,"Lower middle income")/1000000 | E28: =SUMIFS(Countries!$AE$5:$AE$222,Countries!$C$5:$C$222,"Europe & Central Asia",Countries!$D$5:$D$222,"Low income")/1000000 | F28: =SUM(B28:E28) | G28: =IF($F28>0,B28/$F28,0) | H28: =IF($F28>0,C28/$F28,0) | I28: =IF($F28>0,D28/$F28,0) | J28: =IF($F28>0,E28/$F28,0)
A29: Middle East, North Africa, Afghanistan & Pakistan | B29: =SUMIFS(Countries!$AE$5:$AE$222,Countries!$C$5:$C$222,"Middle East, North Africa, Afghanistan & Pakistan",Countries!$D$5:$D$222,"High income")/1000000 | C29: =SUMIFS(Countries!$AE$5:$AE$222,Countries!$C$5:$C$222,"Middle East, North Africa, Afghanistan & Pakistan",Countries!$D$5:$D$222,"Upper middle income")/1000000 | D29: =SUMIFS(Countries!$AE$5:$AE$222,Countries!$C$5:$C$222,"Middle East, North Africa, Afghanistan & Pakistan",Countries!$D$5:$D$222,"Lower middle income")/1000000 | E29: =SUMIFS(Countries!$AE$5:$AE$222,Countries!$C$5:$C$222,"Middle East, North Africa, Afghanistan & Pakistan",Countries!$D$5:$D$222,"Low income")/1000000 | F29: =SUM(B29:E29) | G29: =IF($F29>0,B29/$F29,0) | H29: =IF($F29>0,C29/$F29,0) | I29: =IF($F29>0,D29/$F29,0) | J29: =IF($F29>0,E29/$F29,0)
A30: Latin America & Caribbean | B30: =SUMIFS(Countries!$AE$5:$AE$222,Countries!$C$5:$C$222,"Latin America & Caribbean",Countries!$D$5:$D$222,"High income")/1000000 | C30: =SUMIFS(Countries!$AE$5:$AE$222,Countries!$C$5:$C$222,"Latin America & Caribbean",Countries!$D$5:$D$222,"Upper middle income")/1000000 | D30: =SUMIFS(Countries!$AE$5:$AE$222,Countries!$C$5:$C$222,"Latin America & Caribbean",Countries!$D$5:$D$222,"Lower middle income")/1000000 | E30: =SUMIFS(Countries!$AE$5:$AE$222,Countries!$C$5:$C$222,"Latin America & Caribbean",Countries!$D$5:$D$222,"Low income")/1000000 | F30: =SUM(B30:E30) | G30: =IF($F30>0,B30/$F30,0) | H30: =IF($F30>0,C30/$F30,0) | I30: =IF($F30>0,D30/$F30,0) | J30: =IF($F30>0,E30/$F30,0)
A31: North America | B31: =SUMIFS(Countries!$AE$5:$AE$222,Countries!$C$5:$C$222,"North America",Countries!$D$5:$D$222,"High income")/1000000 | C31: =SUMIFS(Countries!$AE$5:$AE$222,Countries!$C$5:$C$222,"North America",Countries!$D$5:$D$222,"Upper middle income")/1000000 | D31: =SUMIFS(Countries!$AE$5:$AE$222,Countries!$C$5:$C$222,"North America",Countries!$D$5:$D$222,"Lower middle income")/1000000 | E31: =SUMIFS(Countries!$AE$5:$AE$222,Countries!$C$5:$C$222,"North America",Countries!$D$5:$D$222,"Low income")/1000000 | F31: =SUM(B31:E31) | G31: =IF($F31>0,B31/$F31,0) | H31: =IF($F31>0,C31/$F31,0) | I31: =IF($F31>0,D31/$F31,0) | J31: =IF($F31>0,E31/$F31,0)
A32: World | B32: =SUM(B25:B31) | C32: =SUM(C25:C31) | D32: =SUM(D25:D31) | E32: =SUM(E25:E31) | F32: =SUM(F25:F31) | G32: =B32/$F32 | H32: =C32/$F32 | I32: =D32/$F32 | J32: =E32/$F32
A34: 4. Region x income level x age (millions) — every non-empty cell
A35: Region | B35: Income level | C35: 0-14 | D35: 15-24 | E35: 25-34 | F35: 35-44 | G35: 45-54 | H35: 55-64 | I35: 65+ | J35: Total | K35: Countries
A36: East Asia & Pacific | B36: High income | C36: =SUMIFS(Countries!$X$5:$X$222,Countries!$C$5:$C$222,"East Asia & Pacific",Countries!$D$5:$D$222,"High income")/1000000 | D36: =SUMIFS(Countries!$Y$5:$Y$222,Countries!$C$5:$C$222,"East Asia & Pacific",Countries!$D$5:$D$222,"High income")/1000000 | E36: =SUMIFS(Countries!$Z$5:$Z$222,Countries!$C$5:$C$222,"East Asia & Pacific",Countries!$D$5:$D$222,"High income")/1000000 | F36: =SUMIFS(Countries!$AA$5:$AA$222,Countries!$C$5:$C$222,"East Asia & Pacific",Countries!$D$5:$D$222,"High income")/1000000 | G36: =SUMIFS(Countries!$AB$5:$AB$222,Countries!$C$5:$C$222,"East Asia & Pacific",Countries!$D$5:$D$222,"High income")/1000000 | H36: =SUMIFS(Countries!$AC$5:$AC$222,Countries!$C$5:$C$222,"East Asia & Pacific",Countries!$D$5:$D$222,"High income")/1000000 | I36: =SUMIFS(Countries!$AD$5:$AD$222,Countries!$C$5:$C$222,"East Asia & Pacific",Countries!$D$5:$D$222,"High income")/1000000 | J36: =SUM(C36:I36) | K36: =COUNTIFS(Countries!$C$5:$C$222,"East Asia & Pacific",Countries!$D$5:$D$222,"High income")
A37: East Asia & Pacific | B37: Upper middle income | C37: =SUMIFS(Countries!$X$5:$X$222,Countries!$C$5:$C$222,"East Asia & Pacific",Countries!$D$5:$D$222,"Upper middle income")/1000000 | D37: =SUMIFS(Countries!$Y$5:$Y$222,Countries!$C$5:$C$222,"East Asia & Pacific",Countries!$D$5:$D$222,"Upper middle income")/1000000 | E37: =SUMIFS(Countries!$Z$5:$Z$222,Countries!$C$5:$C$222,"East Asia & Pacific",Countries!$D$5:$D$222,"Upper middle income")/1000000 | F37: =SUMIFS(Countries!$AA$5:$AA$222,Countries!$C$5:$C$222,"East Asia & Pacific",Countries!$D$5:$D$222,"Upper middle income")/1000000 | G37: =SUMIFS(Countries!$AB$5:$AB$222,Countries!$C$5:$C$222,"East Asia & Pacific",Countries!$D$5:$D$222,"Upper middle income")/1000000 | H37: =SUMIFS(Countries!$AC$5:$AC$222,Countries!$C$5:$C$222,"East Asia & Pacific",Countries!$D$5:$D$222,"Upper middle income")/1000000 | I37: =SUMIFS(Countries!$AD$5:$AD$222,Countries!$C$5:$C$222,"East Asia & Pacific",Countries!$D$5:$D$222,"Upper middle income")/1000000 | J37: =SUM(C37:I37) | K37: =COUNTIFS(Countries!$C$5:$C$222,"East Asia & Pacific",Countries!$D$5:$D$222,"Upper middle income")
A38: East Asia & Pacific | B38: Lower middle income | C38: =SUMIFS(Countries!$X$5:$X$222,Countries!$C$5:$C$222,"East Asia & Pacific",Countries!$D$5:$D$222,"Lower middle income")/1000000 | D38: =SUMIFS(Countries!$Y$5:$Y$222,Countries!$C$5:$C$222,"East Asia & Pacific",Countries!$D$5:$D$222,"Lower middle income")/1000000 | E38: =SUMIFS(Countries!$Z$5:$Z$222,Countries!$C$5:$C$222,"East Asia & Pacific",Countries!$D$5:$D$222,"Lower middle income")/1000000 | F38: =SUMIFS(Countries!$AA$5:$AA$222,Countries!$C$5:$C$222,"East Asia & Pacific",Countries!$D$5:$D$222,"Lower middle income")/1000000 | G38: =SUMIFS(Countries!$AB$5:$AB$222,Countries!$C$5:$C$222,"East Asia & Pacific",Countries!$D$5:$D$222,"Lower middle income")/1000000 | H38: =SUMIFS(Countries!$AC$5:$AC$222,Countries!$C$5:$C$222,"East Asia & Pacific",Countries!$D$5:$D$222,"Lower middle income")/1000000 | I38: =SUMIFS(Countries!$AD$5:$AD$222,Countries!$C$5:$C$222,"East Asia & Pacific",Countries!$D$5:$D$222,"Lower middle income")/1000000 | J38: =SUM(C38:I38) | K38: =COUNTIFS(Countries!$C$5:$C$222,"East Asia & Pacific",Countries!$D$5:$D$222,"Lower middle income")
A39: East Asia & Pacific | B39: Low income | C39: =SUMIFS(Countries!$X$5:$X$222,Countries!$C$5:$C$222,"East Asia & Pacific",Countries!$D$5:$D$222,"Low income")/1000000 | D39: =SUMIFS(Countries!$Y$5:$Y$222,Countries!$C$5:$C$222,"East Asia & Pacific",Countries!$D$5:$D$222,"Low income")/1000000 | E39: =SUMIFS(Countries!$Z$5:$Z$222,Countries!$C$5:$C$222,"East Asia & Pacific",Countries!$D$5:$D$222,"Low income")/1000000 | F39: =SUMIFS(Countries!$AA$5:$AA$222,Countries!$C$5:$C$222,"East Asia & Pacific",Countries!$D$5:$D$222,"Low income")/1000000 | G39: =SUMIFS(Countries!$AB$5:$AB$222,Countries!$C$5:$C$222,"East Asia & Pacific",Countries!$D$5:$D$222,"Low income")/1000000 | H39: =SUMIFS(Countries!$AC$5:$AC$222,Countries!$C$5:$C$222,"East Asia & Pacific",Countries!$D$5:$D$222,"Low income")/1000000 | I39: =SUMIFS(Countries!$AD$5:$AD$222,Countries!$C$5:$C$222,"East Asia & Pacific",Countries!$D$5:$D$222,"Low income")/1000000 | J39: =SUM(C39:I39) | K39: =COUNTIFS(Countries!$C$5:$C$222,"East Asia & Pacific",Countries!$D$5:$D$222,"Low income")
A40: South Asia | B40: Upper middle income | C40: =SUMIFS(Countries!$X$5:$X$222,Countries!$C$5:$C$222,"South Asia",Countries!$D$5:$D$222,"Upper middle income")/1000000 | D40: =SUMIFS(Countries!$Y$5:$Y$222,Countries!$C$5:$C$222,"South Asia",Countries!$D$5:$D$222,"Upper middle income")/1000000 | E40: =SUMIFS(Countries!$Z$5:$Z$222,Countries!$C$5:$C$222,"South Asia",Countries!$D$5:$D$222,"Upper middle income")/1000000 | F40: =SUMIFS(Countries!$AA$5:$AA$222,Countries!$C$5:$C$222,"South Asia",Countries!$D$5:$D$222,"Upper middle income")/1000000 | G40: =SUMIFS(Countries!$AB$5:$AB$222,Countries!$C$5:$C$222,"South Asia",Countries!$D$5:$D$222,"Upper middle income")/1000000 | H40: =SUMIFS(Countries!$AC$5:$AC$222,Countries!$C$5:$C$222,"South Asia",Countries!$D$5:$D$222,"Upper middle income")/1000000 | I40: =SUMIFS(Countries!$AD$5:$AD$222,Countries!$C$5:$C$222,"South Asia",Countries!$D$5:$D$222,"Upper middle income")/1000000 | J40: =SUM(C40:I40) | K40: =COUNTIFS(Countries!$C$5:$C$222,"South Asia",Countries!$D$5:$D$222,"Upper middle income")
A41: South Asia | B41: Lower middle income | C41: =SUMIFS(Countries!$X$5:$X$222,Countries!$C$5:$C$222,"South Asia",Countries!$D$5:$D$222,"Lower middle income")/1000000 | D41: =SUMIFS(Countries!$Y$5:$Y$222,Countries!$C$5:$C$222,"South Asia",Countries!$D$5:$D$222,"Lower middle income")/1000000 | E41: =SUMIFS(Countries!$Z$5:$Z$222,Countries!$C$5:$C$222,"South Asia",Countries!$D$5:$D$222,"Lower middle income")/1000000 | F41: =SUMIFS(Countries!$AA$5:$AA$222,Countries!$C$5:$C$222,"South Asia",Countries!$D$5:$D$222,"Lower middle income")/1000000 | G41: =SUMIFS(Countries!$AB$5:$AB$222,Countries!$C$5:$C$222,"South Asia",Countries!$D$5:$D$222,"Lower middle income")/1000000 | H41: =SUMIFS(Countries!$AC$5:$AC$222,Countries!$C$5:$C$222,"South Asia",Countries!$D$5:$D$222,"Lower middle income")/1000000 | I41: =SUMIFS(Countries!$AD$5:$AD$222,Countries!$C$5:$C$222,"South Asia",Countries!$D$5:$D$222,"Lower middle income")/1000000 | J41: =SUM(C41:I41) | K41: =COUNTIFS(Countries!$C$5:$C$222,"South Asia",Countries!$D$5:$D$222,"Lower middle income")
A42: Sub-Saharan Africa | B42: High income | C42: =SUMIFS(Countries!$X$5:$X$222,Countries!$C$5:$C$222,"Sub-Saharan Africa",Countries!$D$5:$D$222,"High income")/1000000 | D42: =SUMIFS(Countries!$Y$5:$Y$222,Countries!$C$5:$C$222,"Sub-Saharan Africa",Countries!$D$5:$D$222,"High income")/1000000 | E42: =SUMIFS(Countries!$Z$5:$Z$222,Countries!$C$5:$C$222,"Sub-Saharan Africa",Countries!$D$5:$D$222,"High income")/1000000 | F42: =SUMIFS(Countries!$AA$5:$AA$222,Countries!$C$5:$C$222,"Sub-Saharan Africa",Countries!$D$5:$D$222,"High income")/1000000 | G42: =SUMIFS(Countries!$AB$5:$AB$222,Countries!$C$5:$C$222,"Sub-Saharan Africa",Countries!$D$5:$D$222,"High income")/1000000 | H42: =SUMIFS(Countries!$AC$5:$AC$222,Countries!$C$5:$C$222,"Sub-Saharan Africa",Countries!$D$5:$D$222,"High income")/1000000 | I42: =SUMIFS(Countries!$AD$5:$AD$222,Countries!$C$5:$C$222,"Sub-Saharan Africa",Countries!$D$5:$D$222,"High income")/1000000 | J42: =SUM(C42:I42) | K42: =COUNTIFS(Countries!$C$5:$C$222,"Sub-Saharan Africa",Countries!$D$5:$D$222,"High income")
A43: Sub-Saharan Africa | B43: Upper middle income | C43: =SUMIFS(Countries!$X$5:$X$222,Countries!$C$5:$C$222,"Sub-Saharan Africa",Countries!$D$5:$D$222,"Upper middle income")/1000000 | D43: =SUMIFS(Countries!$Y$5:$Y$222,Countries!$C$5:$C$222,"Sub-Saharan Africa",Countries!$D$5:$D$222,"Upper middle income")/1000000 | E43: =SUMIFS(Countries!$Z$5:$Z$222,Countries!$C$5:$C$222,"Sub-Saharan Africa",Countries!$D$5:$D$222,"Upper middle income")/1000000 | F43: =SUMIFS(Countries!$AA$5:$AA$222,Countries!$C$5:$C$222,"Sub-Saharan Africa",Countries!$D$5:$D$222,"Upper middle income")/1000000 | G43: =SUMIFS(Countries!$AB$5:$AB$222,Countries!$C$5:$C$222,"Sub-Saharan Africa",Countries!$D$5:$D$222,"Upper middle income")/1000000 | H43: =SUMIFS(Countries!$AC$5:$AC$222,Countries!$C$5:$C$222,"Sub-Saharan Africa",Countries!$D$5:$D$222,"Upper middle income")/1000000 | I43: =SUMIFS(Countries!$AD$5:$AD$222,Countries!$C$5:$C$222,"Sub-Saharan Africa",Countries!$D$5:$D$222,"Upper middle income")/1000000 | J43: =SUM(C43:I43) | K43: =COUNTIFS(Countries!$C$5:$C$222,"Sub-Saharan Africa",Countries!$D$5:$D$222,"Upper middle income")
A44: Sub-Saharan Africa | B44: Lower middle income | C44: =SUMIFS(Countries!$X$5:$X$222,Countries!$C$5:$C$222,"Sub-Saharan Africa",Countries!$D$5:$D$222,"Lower middle income")/1000000 | D44: =SUMIFS(Countries!$Y$5:$Y$222,Countries!$C$5:$C$222,"Sub-Saharan Africa",Countries!$D$5:$D$222,"Lower middle income")/1000000 | E44: =SUMIFS(Countries!$Z$5:$Z$222,Countries!$C$5:$C$222,"Sub-Saharan Africa",Countries!$D$5:$D$222,"Lower middle income")/1000000 | F44: =SUMIFS(Countries!$AA$5:$AA$222,Countries!$C$5:$C$222,"Sub-Saharan Africa",Countries!$D$5:$D$222,"Lower middle income")/1000000 | G44: =SUMIFS(Countries!$AB$5:$AB$222,Countries!$C$5:$C$222,"Sub-Saharan Africa",Countries!$D$5:$D$222,"Lower middle income")/1000000 | H44: =SUMIFS(Countries!$AC$5:$AC$222,Countries!$C$5:$C$222,"Sub-Saharan Africa",Countries!$D$5:$D$222,"Lower middle income")/1000000 | I44: =SUMIFS(Countries!$AD$5:$AD$222,Countries!$C$5:$C$222,"Sub-Saharan Africa",Countries!$D$5:$D$222,"Lower middle income")/1000000 | J44: =SUM(C44:I44) | K44: =COUNTIFS(Countries!$C$5:$C$222,"Sub-Saharan Africa",Countries!$D$5:$D$222,"Lower middle income")
...

Sheet Age pyramid
A1: World population by 5-year age group and sex, 2025 (millions)
A2: Inputs: World Bank SP.POP.<bin>.FE/.MA for WLD. Both-sexes column cross-checks to the Countries sheet.
A4: Age | B4: Female | C4: Male | D4: Both sexes | E4: % of world | F4: Male per 100 female | G4: Countries sheet | H4: Diff
A5: 0-4 | B5: 313.3979 | C5: 329.2907 | D5: =B5+C5 | E5: =D5/$D$22 | F5: =C5/B5*100 | G5: =Countries!E223/1000000 | H5: =G5-D5
A6: 5-9 | B6: 328.4388 | C6: 347.5716 | D6: =B6+C6 | E6: =D6/$D$22 | F6: =C6/B6*100 | G6: =Countries!F223/1000000 | H6: =G6-D6
A7: 10-14 | B7: 332.4786 | C7: 354.1303 | D7: =B7+C7 | E7: =D7/$D$22 | F7: =C7/B7*100 | G7: =Countries!G223/1000000 | H7: =G7-D7
A8: 15-19 | B8: 318.4854 | C8: 339.5049 | D8: =B8+C8 | E8: =D8/$D$22 | F8: =C8/B8*100 | G8: =Countries!H223/1000000 | H8: =G8-D8
A9: 20-24 | B9: 302.211 | C9: 320.8436 | D9: =B9+C9 | E9: =D9/$D$22 | F9: =C9/B9*100 | G9: =Countries!I223/1000000 | H9: =G9-D9
A10: 25-29 | B10: 291.891 | C10: 309.4862 | D10: =B10+C10 | E10: =D10/$D$22 | F10: =C10/B10*100 | G10: =Countries!J223/1000000 | H10: =G10-D10
A11: 30-34 | B11: 291.0482 | C11: 307.2469 | D11: =B11+C11 | E11: =D11/$D$22 | F11: =C11/B11*100 | G11: =Countries!K223/1000000 | H11: =G11-D11
A12: 35-39 | B12: 292.7822 | C12: 305.937 | D12: =B12+C12 | E12: =D12/$D$22 | F12: =C12/B12*100 | G12: =Countries!L223/1000000 | H12: =G12-D12
A13: 40-44 | B13: 267.3762 | C13: 275.4249 | D13: =B13+C13 | E13: =D13/$D$22 | F13: =C13/B13*100 | G13: =Countries!M223/1000000 | H13: =G13-D13
A14: 45-49 | B14: 238.9745 | C14: 242.7877 | D14: =B14+C14 | E14: =D14/$D$22 | F14: =C14/B14*100 | G14: =Countries!N223/1000000 | H14: =G14-D14
A15: 50-54 | B15: 231.5279 | C15: 230.8924 | D15: =B15+C15 | E15: =D15/$D$22 | F15: =C15/B15*100 | G15: =Countries!O223/1000000 | H15: =G15-D15
A16: 55-59 | B16: 214.9007 | C16: 209.4197 | D16: =B16+C16 | E16: =D16/$D$22 | F16: =C16/B16*100 | G16: =Countries!P223/1000000 | H16: =G16-D16
A17: 60-64 | B17: 187.6796 | C17: 177.0931 | D17: =B17+C17 | E17: =D17/$D$22 | F17: =C17/B17*100 | G17: =Countries!Q223/1000000 | H17: =G17-D17
A18: 65-69 | B18: 154.7269 | C18: 138.7109 | D18: =B18+C18 | E18: =D18/$D$22 | F18: =C18/B18*100 | G18: =Countries!R223/1000000 | H18: =G18-D18
A19: 70-74 | B19: 127.9945 | C19: 107.4061 | D19: =B19+C19 | E19: =D19/$D$22 | F19: =C19/B19*100 | G19: =Countries!S223/1000000 | H19: =G19-D19
A20: 75-79 | B20: 88.3747 | C20: 69.3915 | D20: =B20+C20 | E20: =D20/$D$22 | F20: =C20/B20*100 | G20: =Countries!T223/1000000 | H20: =G20-D20
A21: 80+ | B21: 103.4603 | C21: 64.5391 | D21: =B21+C21 | E21: =D21/$D$22 | F21: =C21/B21*100 | G21: =Countries!U223/1000000 | H21: =G21-D21
A22: Total | B22: =SUM(B5:B21) | C22: =SUM(C5:C21) | D22: =SUM(D5:D21) | F22: =C22/B22*100 | G22: =SUM(G5:G21) | H22: =SUM(H5:H21)

Sheet Countries
A1: Population by country, 2025 (people) — World Bank WDI
A2: Blue = World Bank inputs (people). Black = formulas. Age bands/total/% on the right recalc from the 5-year bins.
A4: ISO3 | B4: Country | C4: Region (World Bank) | D4: Income level (World Bank FY27) | E4: 0-4 | F4: 5-9 | G4: 10-14 | H4: 15-19 | I4: 20-24 | J4: 25-29 | K4: 30-34 | L4: 35-39 | M4: 40-44 | N4: 45-49 | O4: 50-54 | P4: 55-59 | Q4: 60-64 | R4: 65-69 | S4: 70-74 | T4: 75-79 | U4: 80+ | V4: Female | W4: Male | X4: 0-14 | Y4: 15-24 | Z4: 25-34 | AA4: 35-44 | AB4: 45-54 | AC4: 55-64 | AD4: 65+ | AE4: Total | AF4: % of world | AG4: Rank | AH4: 2024 total | AI4: y/y growth | AJ4: GDP/capita (US$) | AK4: Median age (est.) | AL4: Pop 15-64 | AM4: AI user share H1 2025 (Microsoft) | AN4: AI user share Q2 2026 (Microsoft) | AO4: Change, pp | AP4: AI users 15-64, Q2 2026 | AQ4: 15-64 pop where measured | AR4: National source: share (as published) | AS4: Share of | AT4: Age range | AU4: Internet use rate applied | AV4: Pop in age range (WB 2025) | AW4: Users stated by source | AX4: National: AI users | AY4: National: users / pop in age range | AZ4: Tier | BA4: Counted in totals | BB4: National: users counted (A/B) | BC4: Microsoft users, same economies | BD4: Best available: national (A/B) else Microsoft | BE4: Measure | BF4: Period | BG4: Source | BH4: URL
A5: IND | B5: India | C5: South Asia | D5: Lower middle income | E5: 113100739 | F5: 117849385 | G5: 123236045 | H5: 126709180 | I5: 129802301 | J5: 125442776 | K5: 119778229 | L5: 113171272 | M5: 102039924 | N5: 88399551 | O5: 76959688 | P5: 65130783 | Q5: 54262569 | R5: 42982194 | S5: 30844609 | T5: 17977753 | U5: 16178530 | V5: 709090081 | W5: 754775447 | X5: =SUM(E5:G5) | Y5: =SUM(H5:I5) | Z5: =SUM(J5:K5) | AA5: =SUM(L5:M5) | AB5: =SUM(N5:O5) | AC5: =SUM(P5:Q5) | AD5: =SUM(R5:U5) | AE5: =SUM(X5:AD5) | AF5: =AE5/SUM($AE$5:$AE$222) | AG5: =RANK(AE5,$AE$5:$AE$222) | AH5: 1450935791 | AI5: =IF(AH5>0,AE5/AH5-1,"") | AJ5: 2702 | AK5: =IF(SUM($E5:E5)>=AE5/2,0+5*(AE5/2-0)/E5,IF(SUM($E5:F5)>=AE5/2,5+5*(AE5/2-SUM($E5:E5))/F5,IF(SUM($E5:G5)>=AE5/2,10+5*(AE5/2-SUM($E5:F5))/G5,IF(SUM($E5:H5)>=AE5/2,15+5*(AE5/2-SUM($E5:G5))/H5,IF(SUM($E5:I5)>=AE5/2,20+5*(AE5/2-SUM($E5:H5))/I5,IF(SUM($E5:J5)>=AE5/2,25+5*(AE5/2-SUM($E5:I5))/J5,IF(SUM($E5:K5)>=AE5/2,30+5*(AE5/2-SUM($E5:J5))/K5,IF(SUM($E5:L5)>=AE5/2,35+5*(AE5/2-SUM($E5:K5))/L5,IF(SUM($E5:M5)>=AE5/2,40+5*(AE5/2-SUM($E5:L5))/M5,IF(SUM($E5:N5)>=AE5/2,45+5*(AE5/2-SUM($E5:M5))/N5,IF(SUM($E5:O5)>=AE5/2,50+5*(AE5/2-SUM($E5:N5))/O5,IF(SUM($E5:P5)>=AE5/2,55+5*(AE5/2-SUM($E5:O5))/P5,IF(SUM($E5:Q5)>=AE5/2,60+5*(AE5/2-SUM($E5:P5))/Q5,IF(SUM($E5:R5)>=AE5/2,65+5*(AE5/2-SUM($E5:Q5))/R5,IF(SUM($E5:S5)>=AE5/2,70+5*(AE5/2-SUM($E5:R5))/S5,IF(SUM($E5:T5)>=AE5/2,75+5*(AE5/2-SUM($E5:S5))/T5,"")))))))))))))))) | AL5: =SUM(H5:Q5) | AM5: 0.142 | AN5: 0.185 | AO5: =IF(AND(ISNUMBER(AN5),ISNUMBER(AM5)),(AN5-AM5)*100,"") | AP5: =IF(ISNUMBER(AN5),AN5*AL5,"") | AQ5: =IF(ISNUMBER(AN5),AL5,0) | AR5: 0.671 | AS5: population | AT5: 18-64 | AU5: 1 | AV5: =H5*0.4+I5+J5+K5+L5+M5+N5+O5+P5+Q5 | AX5: =IF(ISNUMBER(AW5),AW5,AR5*AU5*AV5) | AY5: =AX5/AV5 | AZ5: C | BA5: No | BB5: =IF(BA5="Yes",AX5,0) | BC5: =IF(AND(BA5="Yes",ISNUMBER(AP5)),AP5,0) | BD5: =IF(BA5="Yes",AX5,IF(ISNUMBER(AP5),AP5,0)) | BE5: Use generative AI at work or outside work | BF5: January-February 2026 (online crowd-worker panel + rural Uttar Pradesh, n=1,795) | BG5: Rutgers University (K. Garimella): Generative AI Adoption in India (working paper) | BH5: http://gvrkiran.github.io/content/GenerativeAI_India_Survey.pdf
A6: CHN | B6: China | C6: East Asia & Pacific | D6: Upper middle income | E6: 47200976 | F6: 79780359 | G6: 89735308 | H6: 84092471 | I6: 78296304 | J6: 82248431 | K6: 97934186 | L6: 120712368 | M6: 101808351 | N6: 91740322 | O6: 114306611 | P6: 115880929 | Q6: 93106428 | R6: 69581264 | S6: 64697646 | T6: 38789301 | U6: 36673748 | V6: 690538987 | W6: 716046016 | X6: =SUM(E6:G6) | Y6: =SUM(H6:I6) | Z6: =SUM(J6:K6) | AA6: =SUM(L6:M6) | AB6: =SUM(N6:O6) | AC6: =SUM(P6:Q6) | AD6: =SUM(R6:U6) | AE6: =SUM(X6:AD6) | AF6: =AE6/SUM($AE$5:$AE$222) | AG6: =RANK(AE6,$AE$5:$AE$222) | AH6: 1408975000 | AI6: =IF(AH6>0,AE6/AH6-1,"") | AJ6: 13862 | AK6: =IF(SUM($E6:E6)>=AE6/2,0+5*(AE6/2-0)/E6,IF(SUM($E6:F6)>=AE6/2,5+5*(AE6/2-SUM($E6:E6))/F6,IF(SUM($E6:G6)>=AE6/2,10+5*(AE6/2-SUM($E6:F6))/G6,IF(SUM($E6:H6)>=AE6/2,15+5*(AE6/2-SUM($E6:G6))/H6,IF(SUM($E6:I6)>=AE6/2,20+5*(AE6/2-SUM($E6:H6))/I6,IF(SUM($E6:J6)>=AE6/2,25+5*(AE6/2-SUM($E6:I6))/J6,IF(SUM($E6:K6)>=AE6/2,30+5*(AE6/2-SUM($E6:J6))/K6,IF(SUM($E6:L6)>=AE6/2,35+5*(AE6/2-SUM($E6:K6))/L6,IF(SUM($E6:M6)>=AE6/2,40+5*(AE6/2-SUM($E6:L6))/M6,IF(SUM($E6:N6)>=AE6/2,45+5*(AE6/2-SUM($E6:M6))/N6,IF(SUM($E6:O6)>=AE6/2,50+5*(AE6/2-SUM($E6:N6))/O6,IF(SUM($E6:P6)>=AE6/2,55+5*(AE6/2-SUM($E6:O6))/P6,IF(SUM($E6:Q6)>=AE6/2,60+5*(AE6/2-SUM($E6:P6))/Q6,IF(SUM($E6:R6)>=AE6/2,65+5*(AE6/2-SUM($E6:Q6))/R6,IF(SUM($E6:S6)>=AE6/2,70+5*(AE6/2-SUM($E6:R6))/S6,IF(SUM($E6:T6)>=AE6/2,75+5*(AE6/2-SUM($E6:S6))/T6,"")))))))))))))))) | AL6: =SUM(H6:Q6) | AM6: 0.154 | AN6: 0.175 | AO6: =IF(AND(ISNUMBER(AN6),ISNUMBER(AM6)),(AN6-AM6)*100,"") | AP6: =IF(ISNUMBER(AN6),AN6*AL6,"") | AQ6: =IF(ISNUMBER(AN6),AL6,0) | AR6: 0.428 | AS6: population | AT6: 0+ | AU6: 1 | AV6: =E6+F6+G6+H6+I6+J6+K6+L6+M6+N6+O6+P6+Q6+R6+S6+T6+U6 | AW6: 602000000 | AX6: =IF(ISNUMBER(AW6),AW6,AR6*AU6*AV6) | AY6: =AX6/AV6 | AZ6: A | BA6: Yes | BB6: =IF(BA6="Yes",AX6,0) | BC6: =IF(AND(BA6="Yes",ISNUMBER(AP6)),AP6,0) | BD6: =IF(BA6="Yes",AX6,IF(ISNUMBER(AP6),AP6,0)) | BE6: Used a generative AI product or service in the past six months (share of the whole population; respondents aged 6+) | BF6: December 2025 (half-yearly telephone survey) | BG6: CNNIC (China Internet Network Information Center): 57th Statistical Report on China's Internet Development, ch. 4 | BH6: https://www.cnnic.cn/NMediaFile/2026/0304/MAIN1772588317069TUXN3827X8.pdf
A7: USA | B7: United States | C7: North America | D7: High income | E7: 18280839 | F7: 19432529 | G7: 20728567 | H7: 22468037 | I7: 22697165 | J7: 22283311 | K7: 23589133 | L7: 23728496 | M7: 22846638 | N7: 21117033 | O7: 20181881 | P7: 20389477 | Q7: 21197000 | R7: 19742816 | S7: 16259262 | T7: 12495721 | U7: 14346951 | V7: 170047087 | W7: 171737769 | X7: =SUM(E7:G7) | Y7: =SUM(H7:I7) | Z7: =SUM(J7:K7) | AA7: =SUM(L7:M7) | AB7: =SUM(N7:O7) | AC7: =SUM(P7:Q7) | AD7: =SUM(R7:U7) | AE7: =SUM(X7:AD7) | AF7: =AE7/SUM($AE$5:$AE$222) | AG7: =RANK(AE7,$AE$5:$AE$222) | AH7: 340003797 | AI7: =IF(AH7>0,AE7/AH7-1,"") | AJ7: 90027 | AK7: =IF(SUM($E7:E7)>=AE7/2,0+5*(AE7/2-0)/E7,IF(SUM($E7:F7)>=AE7/2,5+5*(AE7/2-SUM($E7:E7))/F7,IF(SUM($E7:G7)>=AE7/2,10+5*(AE7/2-SUM($E7:F7))/G7,IF(SUM($E7:H7)>=AE7/2,15+5*(AE7/2-SUM($E7:G7))/H7,IF(SUM($E7:I7)>=AE7/2,20+5*(AE7/2-SUM($E7:H7))/I7,IF(SUM($E7:J7)>=AE7/2,25+5*(AE7/2-SUM($E7:I7))/J7,IF(SUM($E7:K7)>=AE7/2,30+5*(AE7/2-SUM($E7:J7))/K7,IF(SUM($E7:L7)>=AE7/2,35+5*(AE7/2-SUM($E7:K7))/L7,IF(SUM($E7:M7)>=AE7/2,40+5*(AE7/2-SUM($E7:L7))/M7,IF(SUM($E7:N7)>=AE7/2,45+5*(AE7/2-SUM($E7:M7))/N7,IF(SUM($E7:O7)>=AE7/2,50+5*(AE7/2-SUM($E7:N7))/O7,IF(SUM($E7:P7)>=AE7/2,55+5*(AE7/2-SUM($E7:O7))/P7,IF(SUM($E7:Q7)>=AE7/2,60+5*(AE7/2-SUM($E7:P7))/Q7,IF(SUM($E7:R7)>=AE7/2,65+5*(AE7/2-SUM($E7:Q7))/R7,IF(SUM($E7:S7)>=AE7/2,70+5*(AE7/2-SUM($E7:R7))/S7,IF(SUM($E7:T7)>=AE7/2,75+5*(AE7/2-SUM($E7:S7))/T7,"")))))))))))))))) | AL7: =SUM(H7:Q7) | AM7: 0.263 | AN7: 0.33 | AO7: =IF(AND(ISNUMBER(AN7),ISNUMBER(AM7)),(AN7-AM7)*100,"") | AP7: =IF(ISNUMBER(AN7),AN7*AL7,"") | AQ7: =IF(ISNUMBER(AN7),AL7,0) | AR7: 0.6178 | AS7: population | AT7: 18-64 | AU7: 1 | AV7: =H7*0.4+I7+J7+K7+L7+M7+N7+O7+P7+Q7 | AX7: =IF(ISNUMBER(AW7),AW7,AR7*AU7*AV7) | AY7: =AX7/AV7 | AZ7: B | BA7: Yes | BB7: =IF(BA7="Yes",AX7,0) | BC7: =IF(AND(BA7="Yes",ISNUMBER(AP7)),AP7,0) | BD7: =IF(BA7="Yes",AX7,IF(ISNUMBER(AP7),AP7,0)) | BE7: Use generative AI for any purpose (for work or outside work) | BF7: Q2 2026 | BG7: Federal Reserve Bank of St. Louis (Real-Time Population Survey; Bick, Blandin and Deming): FRED series RPSGENAIUSAGESHAREALL: Generative AI adoption rate overall, working-age adults | BH7: https://fred.stlouisfed.org/series/RPSGENAIUSAGESHAREALL
A8: IDN | B8: Indonesia | C8: East Asia & Pacific | D8: Upper middle income | E8: 22097071 | F8: 22828956 | G8: 24353517 | H8: 23553644 | I8: 22033791 | J8: 22039806 | K8: 21228255 | L8: 20713744 | M8: 20843679 | N8: 19394513 | O8: 17488359 | P8: 15280690 | Q8: 12313918 | R8: 9081522 | S8: 5882056 | T8: 3493972 | U8: 3093744 | V8: 142193716 | W8: 143527521 | X8: =SUM(E8:G8) | Y8: =SUM(H8:I8) | Z8: =SUM(J8:K8) | AA8: =SUM(L8:M8) | AB8: =SUM(N8:O8) | AC8: =SUM(P8:Q8) | AD8: =SUM(R8:U8) | AE8: =SUM(X8:AD8) | AF8: =AE8/SUM($AE$5:$AE$222) | AG8: =RANK(AE8,$AE$5:$AE$222) | AH8: 283487931 | AI8: =IF(AH8>0,AE8/AH8-1,"") | AJ8: 5060 | AK8: =IF(SUM($E8:E8)>=AE8/2,0+5*(AE8/2-0)/E8,IF(SUM($E8:F8)>=AE8/2,5+5*(AE8/2-SUM($E8:E8))/F8,IF(SUM($E8:G8)>=AE8/2,10+5*(AE8/2-SUM($E8:F8))/G8,IF(SUM($E8:H8)>=AE8/2,15+5*(AE8/2-SUM($E8:G8))/H8,IF(SUM($E8:I8)>=AE8/2,20+5*(AE8/2-SUM($E8:H8))/I8,IF(SUM($E8:J8)>=AE8/2,25+5*(AE8/2-SUM($E8:I8))/J8,IF(SUM($E8:K8)>=AE8/2,30+5*(AE8/2-SUM($E8:J8))/K8,IF(SUM($E8:L8)>=AE8/2,35+5*(AE8/2-SUM($E8:K8))/L8,IF(SUM($E8:M8)>=AE8/2,40+5*(AE8/2-SUM($E8:L8))/M8,IF(SUM($E8:N8)>=AE8/2,45+5*(AE8/2-SUM($E8:M8))/N8,IF(SUM($E8:O8)>=AE8/2,50+5*(AE8/2-SUM($E8:N8))/O8,IF(SUM($E8:P8)>=AE8/2,55+5*(AE8/2-SUM($E8:O8))/P8,IF(SUM($E8:Q8)>=AE8/2,60+5*(AE8/2-SUM($E8:P8))/Q8,IF(SUM($E8:R8)>=AE8/2,65+5*(AE8/2-SUM($E8:Q8))/R8,IF(SUM($E8:S8)>=AE8/2,70+5*(AE8/2-SUM($E8:R8))/S8,IF(SUM($E8:T8)>=AE8/2,75+5*(AE8/2-SUM($E8:S8))/T8,"")))))))))))))))) | AL8: =SUM(H8:Q8) | AM8: 0.117 | AN8: 0.148 | AO8: =IF(AND(ISNUMBER(AN8),ISNUMBER(AM8)),(AN8-AM8)*100,"") | AP8: =IF(ISNUMBER(AN8),AN8*AL8,"") | AQ8: =IF(ISNUMBER(AN8),AL8,0) | AR8: 0.182 | AS8: population | AT8: 13+ | AU8: 1 | AV8: =G8*0.4+H8+I8+J8+K8+L8+M8+N8+O8+P8+Q8+R8+S8+T8+U8 | AX8: =IF(ISNUMBER(AW8),AW8,AR8*AU8*AV8) | AY8: =AX8/AV8 | AZ8: A | BA8: No | BB8: =IF(BA8="Yes",AX8,0) | BC8: =IF(AND(BA8="Yes",ISNUMBER(AP8)),AP8,0) | BD8: =IF(BA8="Yes",AX8,IF(ISNUMBER(AP8),AP8,0)) | BE8: Access to artificial intelligence (any AI, including chatbots, writing tools and voice assistants) | BF8: 1 February - 15 March 2026 (face-to-face, n=8,700) | BG8: APJII (Indonesian Internet Service Providers Association): Indonesia Internet Penetration and Behaviour Survey 2026, p. 123 | BH8: https://survei.apjii.or.id/uploads/1790827973204-Survei-Penetrasi-Internet-dan-Perilaku-Penggunaan-Internet-2026.pdf
A9: PAK | B9: Pakistan | C9: Middle East, North Africa, Afghanistan & Pakistan | D9: Lower middle income | E9: 32134104 | F9: 30419761 | G9: 29948170 | H9: 27329487 | I9: 23603539 | J9: 20687491 | K9: 18010398 | L9: 15645925 | M9: 13245154 | N9: 10615101 | O9: 8806085 | P9: 7423705 | Q9: 6218304 | R9: 4729639 | S9: 3086275 | T9: 1879843 | U9: 1436566 | V9: 125904871 | W9: 129314676 | X9: =SUM(E9:G9) | Y9: =SUM(H9:I9) | Z9: =SUM(J9:K9) | AA9: =SUM(L9:M9) | AB9: =SUM(N9:O9) | AC9: =SUM(P9:Q9) | AD9: =SUM(R9:U9) | AE9: =SUM(X9:AD9) | AF9: =AE9/SUM($AE$5:$AE$222) | AG9: =RANK(AE9,$AE$5:$AE$222) | AH9: 251269164 | AI9: =IF(AH9>0,AE9/AH9-1,"") | AJ9: 1596 | AK9: =IF(SUM($E9:E9)>=AE9/2,0+5*(AE9/2-0)/E9,IF(SUM($E9:F9)>=AE9/2,5+5*(AE9/2-SUM($E9:E9))/F9,IF(SUM($E9:G9)>=AE9/2,10+5*(AE9/2-SUM($E9:F9))/G9,IF(SUM($E9:H9)>=AE9/2,15+5*(AE9/2-SUM($E9:G9))/H9,IF(SUM($E9:I9)>=AE9/2,20+5*(AE9/2-SUM($E9:H9))/I9,IF(SUM($E9:J9)>=AE9/2,25+5*(AE9/2-SUM($E9:I9))/J9,IF(SUM($E9:K9)>=AE9/2,30+5*(AE9/2-SUM($E9:J9))/K9,IF(SUM($E9:L9)>=AE9/2,35+5*(AE9/2-SUM($E9:K9))/L9,IF(SUM($E9:M9)>=AE9/2,40+5*(AE9/2-SUM($E9:L9))/M9,IF(SUM($E9:N9)>=AE9/2,45+5*(AE9/2-SUM($E9:M9))/N9,IF(SUM($E9:O9)>=AE9/2,50+5*(AE9/2-SUM($E9:N9))/O9,IF(SUM($E9:P9)>=AE9/2,55+5*(AE9/2-SUM($E9:O9))/P9,IF(SUM($E9:Q9)>=AE9/2,60+5*(AE9/2-SUM($E9:P9))/Q9,IF(SUM($E9:R9)>=AE9/2,65+5*(AE9/2-SUM($E9:Q9))/R9,IF(SUM($E9:S9)>=AE9/2,70+5*(AE9/2-SUM($E9:R9))/S9,IF(SUM($E9:T9)>=AE9/2,75+5*(AE9/2-SUM($E9:S9))/T9,"")))))))))))))))) | AL9: =SUM(H9:Q9) | AM9: 0.097 | AN9: 0.119 | AO9: =IF(AND(ISNUMBER(AN9),ISNUMBER(AM9)),(AN9-AM9)*100,"") | AP9: =IF(ISNUMBER(AN9),AN9*AL9,"") | AQ9: =IF(ISNUMBER(AN9),AL9,0) | AR9: 0.024 | AS9: population | AT9: 0+ | AU9: 1 | AV9: =E9+F9+G9+H9+I9+J9+K9+L9+M9+N9+O9+P9+Q9+R9+S9+T9+U9 | AW9: 6000000 | AX9: =IF(ISNUMBER(AW9),AW9,AR9*AU9*AV9) | AY9: =AX9/AV9 | AZ9: C | BA9: No | BB9: =IF(BA9="Yes",AX9,0) | BC9: =IF(AND(BA9="Yes",ISNUMBER(AP9)),AP9,0) | BD9: =IF(BA9="Yes",AX9,IF(ISNUMBER(AP9),AP9,0)) | BE9: Use generative AI (about 6 million users) | BF9: March 2024 (phone survey of internet users) | BG9: Ipsos Pakistan: Gen. AI in Pakistan: Knowledge, Perceptions, and Usage | BH9: https://www.ipsos.com/sites/default/files/ct/news/documents/2024-07/Gen.%20AI%20in%20Pakistan_0.pdf
A10: NGA | B10: Nigeria | C10: Sub-Saharan Africa | D10: Lower middle income | E10: 34221128 | F10: 31747790 | G10: 30276683 | H10: 26858427 | I10: 22798374 | J10: 18257168 | K10: 15162389 | L10: 12880664 | M10: 11276784 | N10: 9472830 | O10: 7339696 | P10: 5625634 | Q10: 4319218 | R10: 3163582 | S10: 2099863 | T10: 1215091 | U10: 812467 | V10: 117350047 | W10: 120177741 | X10: =SUM(E10:G10) | Y10: =SUM(H10:I10) | Z10: =SUM(J10:K10) | AA10: =SUM(L10:M10) | AB10: =SUM(N10:O10) | AC10: =SUM(P10:Q10) | AD10: =SUM(R10:U10) | AE10: =SUM(X10:AD10) | AF10: =AE10/SUM($AE$5:$AE$222) | AG10: =RANK(AE10,$AE$5:$AE$222) | AH10: 232679478 | AI10: =IF(AH10>0,AE10/AH10-1,"") | AJ10: 1224 | AK10: =IF(SUM($E10:E10)>=AE10/2,0+5*(AE10/2-0)/E10,IF(SUM($E10:F10)>=AE10/2,5+5*(AE10/2-SUM($E10:E10))/F10,IF(SUM($E10:G10)>=AE10/2,10+5*(AE10/2-SUM($E10:F10))/G10,IF(SUM($E10:H10)>=AE10/2,15+5*(AE10/2-SUM($E10:G10))/H10,IF(SUM($E10:I10)>=AE10/2,20+5*(AE10/2-SUM($E10:H10))/I10,IF(SUM($E10:J10)>=AE10/2,25+5*(AE10/2-SUM($E10:I10))/J10,IF(SUM($E10:K10)>=AE10/2,30+5*(AE10/2-SUM($E10:J10))/K10,IF(SUM($E10:L10)>=AE10/2,35+5*(AE10/2-SUM($E10:K10))/L10,IF(SUM($E10:M10)>=AE10/2,40+5*(AE10/2-SUM($E10:L10))/M10,IF(SUM($E10:N10)>=AE10/2,45+5*(AE10/2-SUM($E10:M10))/N10,IF(SUM($E10:O10)>=AE10/2,50+5*(AE10/2-SUM($E10:N10))/O10,IF(SUM($E10:P10)>=AE10/2,55+5*(AE10/2-SUM($E10:O10))/P10,IF(SUM($E10:Q10)>=AE10/2,60+5*(AE10/2-SUM($E10:P10))/Q10,IF(SUM($E10:R10)>=AE10/2,65+5*(AE10/2-SUM($E10:Q10))/R10,IF(SUM($E10:S10)>=AE10/2,70+5*(AE10/2-SUM($E10:R10))/S10,IF(SUM($E10:T10)>=AE10/2,75+5*(AE10/2-SUM($E10:S10))/T10,"")))))))))))))))) | AL10: =SUM(H10:Q10) | AM10: 0.087 | AN10: 0.104 | AO10: =IF(AND(ISNUMBER(AN10),ISNUMBER(AM10)),(AN10-AM10)*100,"") | AP10: =IF(ISNUMBER(AN10),AN10*AL10,"") | AQ10: =IF(ISNUMBER(AN10),AL10,0) | AR10: 0.2 | AS10: population | AT10: 15+ | AU10: 1 | AV10: =H10+I10+J10+K10+L10+M10+N10+O10+P10+Q10+R10+S10+T10+U10 | AX10: =IF(ISNUMBER(AW10),AW10,AR10*AU10*AV10) | AY10: =AX10/AV10 | AZ10: C | BA10: No | BB10: =IF(BA10="Yes",AX10,0) | BC10: =IF(AND(BA10="Yes",ISNUMBER(AP10)),AP10,0) | BD10: =IF(BA10="Yes",AX10,IF(ISNUMBER(AP10),AP10,0)) | BE10: Have ever used AI (daily, weekly or monthly or less) | BF10: April-July 2026 (Gallup World Poll, probability sample ~1,000) | BG10: Gallup (World Poll; research run with Microsoft): AI Optimism Globally Widespread Despite Uneven Use | BH10: https://news.gallup.com/poll/714593/optimism-globally-widespread-despite-uneven.aspx
A11: BRA | B11: Brazil | C11: Latin America & Caribbean | D11: Upper middle income | E11: 12879996 | F11: 13992561 | G11: 14384578 | H11: 14693839 | I11: 15466284 | J11: 16326070 | K11: 16012011 | L11: 16507612 | M11: 16634889 | N11: 15189013 | O11: 13356306 | P11: 11989336 | Q11: 10948325 | R11: 8928228 | S11: 6696597 | T11: 4438135 | U11: 4368627 | V11: 108154994 | W11: 104657413 | X11: =SUM(E11:G11) | Y11: =SUM(H11:I11) | Z11: =SUM(J11:K11) | AA11: =SUM(L11:M11) | AB11: =SUM(N11:O11) | AC11: =SUM(P11:Q11) | AD11: =SUM(R11:U11) | AE11: =SUM(X11:AD11) | AF11: =AE11/SUM($AE$5:$AE$222) | AG11: =RANK(AE11,$AE$5:$AE$222) | AH11: 211998573 | AI11: =IF(AH11>0,AE11/AH11-1,"") | AJ11: 10713 | AK11: =IF(SUM($E11:E11)>=AE11/2,0+5*(AE11/2-0)/E11,IF(SUM($E11:F11)>=AE11/2,5+5*(AE11/2-SUM($E11:E11))/F11,IF(SUM($E11:G11)>=AE11/2,10+5*(AE11/2-SUM($E11:F11))/G11,IF(SUM($E11:H11)>=AE11/2,15+5*(AE11/2-SUM($E11:G11))/H11,IF(SUM($E11:I11)>=AE11/2,20+5*(AE11/2-SUM($E11:H11))/I11,IF(SUM($E11:J11)>=AE11/2,25+5*(AE11/2-SUM($E11:I11))/J11,IF(SUM($E11:K11)>=AE11/2,30+5*(AE11/2-SUM($E11:J11))/K11,IF(SUM($E11:L11)>=AE11/2,35+5*(AE11/2-SUM($E11:K11))/L11,IF(SUM($E11:M11)>=AE11/2,40+5*(AE11/2-SUM($E11:L11))/M11,IF(SUM($E11:N11)>=AE11/2,45+5*(AE11/2-SUM($E11:M11))/N11,IF(SUM($E11:O11)>=AE11/2,50+5*(AE11/2-SUM($E11:N11))/O11,IF(SUM($E11:P11)>=AE11/2,55+5*(AE11/2-SUM($E11:O11))/P11,IF(SUM($E11:Q11)>=AE11/2,60+5*(AE11/2-SUM($E11:P11))/Q11,IF(SUM($E11:R11)>=AE11/2,65+5*(AE11/2-SUM($E11:Q11))/R11,IF(SUM($E11:S11)>=AE11/2,70+5*(AE11/2-SUM($E11:R11))/S11,IF(SUM($E11:T11)>=AE11/2,75+5*(AE11/2-SUM($E11:S11))/T11,"")))))))))))))))) | AL11: =SUM(H11:Q11) | AM11: 0.156 | AN11: 0.202 | AO11: =IF(AND(ISNUMBER(AN11),ISNUMBER(AM11)),(AN11-AM11)*100,"") | AP11: =IF(ISNUMBER(AN11),AN11*AL11,"") | AQ11: =IF(ISNUMBER(AN11),AL11,0) | AR11: 0.32 | AS11: internet users | AT11: 10+ | AU11: 1 | AV11: =G11+H11+I11+J11+K11+L11+M11+N11+O11+P11+Q11+R11+S11+T11+U11 | AW11: 50000000 | AX11: =IF(ISNUMBER(AW11),AW11,AR11*AU11*AV11) | AY11: =AX11/AV11 | AZ11: A | BA11: Yes | BB11: =IF(BA11="Yes",AX11,0) | BC11: =IF(AND(BA11="Yes",ISNUMBER(AP11)),AP11,0) | BD11: =IF(BA11="Yes",AX11,IF(ISNUMBER(AP11),AP11,0)) | BE11: Used generative AI tools in the three months before the survey (share of internet users aged 10+) | BF11: March-September 2025 (face-to-face household survey) | BG11: CETIC.br / NIC.br (runs Brazil's official household ICT survey): TIC Domicilios 2025, executive summary | BH11: https://www.cetic.br/media/docs/publicacoes/2/pt-br/20260511173151/tic_domicilios_2025_resumoexecutivo%20pt.pdf
A12: BGD | B12: Bangladesh | C12: South Asia | D12: Lower middle income | E12: 16831404 | F12: 15775080 | G12: 15963465 | H12: 16947603 | I12: 16305496 | J12: 15136342 | K12: 13612547 | L12: 12424100 | M12: 11963002 | N12: 9240182 | O12: 7834688 | P12: 6566376 | Q12: 5371067 | R12: 4301863 | S12: 3283502 | T12: 2115696 | U12: 2014483 | V12: 89320167 | W12: 86366729 | X12: =SUM(E12:G12) | Y12: =SUM(H12:I12) | Z12: =SUM(J12:K12) | AA12: =SUM(L12:M12) | AB12: =SUM(N12:O12) | AC12: =SUM(P12:Q12) | AD12: =SUM(R12:U12) | AE12: =SUM(X12:AD12) | AF12: =AE12/SUM($AE$5:$AE$222) | AG12: =RANK(AE12,$AE$5:$AE$222) | AH12: 173562364 | AI12: =IF(AH12>0,AE12/AH12-1,"") | AJ12: 2597 | AK12: =IF(SUM($E12:E12)>=AE12/2,0+5*(AE12/2-0)/E12,IF(SUM($E12:F12)>=AE12/2,5+5*(AE12/2-SUM($E12:E12))/F12,IF(SUM($E12:G12)>=AE12/2,10+5*(AE12/2-SUM($E12:F12))/G12,IF(SUM($E12:H12)>=AE12/2,15+5*(AE12/2-SUM($E12:G12))/H12,IF(SUM($E12:I12)>=AE12/2,20+5*(AE12/2-SUM($E12:H12))/I12,IF(SUM($E12:J12)>=AE12/2,25+5*(AE12/2-SUM($E12:I12))/J12,IF(SUM($E12:K12)>=AE12/2,30+5*(AE12/2-SUM($E12:J12))/K12,IF(SUM($E12:L12)>=AE12/2,35+5*(AE12/2-SUM($E12:K12))/L12,IF(SUM($E12:M12)>=AE12/2,40+5*(AE12/2-SUM($E12:L12))/M12,IF(SUM($E12:N12)>=AE12/2,45+5*(AE12/2-SUM($E12:M12))/N12,IF(SUM($E12:O12)>=AE12/2,50+5*(AE12/2-SUM($E12:N12))/O12,IF(SUM($E12:P12)>=AE12/2,55+5*(AE12/2-SUM($E12:O12))/P12,IF(SUM($E12:Q12)>=AE12/2,60+5*(AE12/2-SUM($E12:P12))/Q12,IF(SUM($E12:R12)>=AE12/2,65+5*(AE12/2-SUM($E12:Q12))/R12,IF(SUM($E12:S12)>=AE12/2,70+5*(AE12/2-SUM($E12:R12))/S12,IF(SUM($E12:T12)>=AE12/2,75+5*(AE12/2-SUM($E12:S12))/T12,"")))))))))))))))) | AL12: =SUM(H12:Q12) | AM12: 0.065 | AN12: 0.08 | AO12: =IF(AND(ISNUMBER(AN12),ISNUMBER(AM12)),(AN12-AM12)*100,"") | AP12: =IF(ISNUMBER(AN12),AN12*AL12,"") | AQ12: =IF(ISNUMBER(AN12),AL12,0) | AR12: 0.101 | AS12: population | AT12: 15+ | AU12: 1 | AV12: =H12+I12+J12+K12+L12+M12+N12+O12+P12+Q12+R12+S12+T12+U12 | AX12: =IF(ISNUMBER(AW12),AW12,AR12*AU12*AV12) | AY12: =AX12/AV12 | AZ12: C | BA12: No | BB12: =IF(BA12="Yes",AX12,0) | BC12: =IF(AND(BA12="Yes",ISNUMBER(AP12)),AP12,0) | BD12: =IF(BA12="Yes",AX12,IF(ISNUMBER(AP12),AP12,0)) | BE12: Have ever used AI (daily, weekly or monthly or less) | BF12: April-July 2026 (Gallup World Poll, probability sample ~1,000) | BG12: Gallup (World Poll; research run with Microsoft): AI Optimism Globally Widespread Despite Uneven Use | BH12: https://news.gallup.com/poll/714593/optimism-globally-widespread-despite-uneven.aspx
A13: RUS | B13: Russian Federation | C13: Europe & Central Asia | D13: High income | E13: 6621862 | F13: 8422666 | G13: 9392182 | H13: 8144016 | I13: 7432843 | J13: 6994540 | K13: 9046859 | L13: 12481388 | M13: 11662998 | N13: 10560530 | O13: 9530700 | P13: 8299594 | Q13: 9389564 | R13: 9054365 | S13: 7079660 | T13: 4609330 | U13: 4790231 | V13: 76960071 | W13: 66553257 | X13: =SUM(E13:G13) | Y13: =SUM(H13:I13) | Z13: =SUM(J13:K13) | AA13: =SUM(L13:M13) | AB13: =SUM(N13:O13) | AC13: =SUM(P13:Q13) | AD13: =SUM(R13:U13) | AE13: =SUM(X13:AD13) | AF13: =AE13/SUM($AE$5:$AE$222) | AG13: =RANK(AE13,$AE$5:$AE$222) | AH13: 143669648 | AI13: =IF(AH13>0,AE13/AH13-1,"") | AJ13: 17547 | AK13: =IF(SUM($E13:E13)>=AE13/2,0+5*(AE13/2-0)/E13,IF(SUM($E13:F13)>=AE13/2,5+5*(AE13/2-SUM($E13:E13))/F13,IF(SUM($E13:G13)>=AE13/2,10+5*(AE13/2-SUM($E13:F13))/G13,IF(SUM($E13:H13)>=AE13/2,15+5*(AE13/2-SUM($E13:G13))/H13,IF(SUM($E13:I13)>=AE13/2,20+5*(AE13/2-SUM($E13:H13))/I13,IF(SUM($E13:J13)>=AE13/2,25+5*(AE13/2-SUM($E13:I13))/J13,IF(SUM($E13:K13)>=AE13/2,30+5*(AE13/2-SUM($E13:J13))/K13,IF(SUM($E13:L13)>=AE13/2,35+5*(AE13/2-SUM($E13:K13))/L13,IF(SUM($E13:M13)>=AE13/2,40+5*(AE13/2-SUM($E13:L13))/M13,IF(SUM($E13:N13)>=AE13/2,45+5*(AE13/2-SUM($E13:M13))/N13,IF(SUM($E13:O13)>=AE13/2,50+5*(AE13/2-SUM($E13:N13))/O13,IF(SUM($E13:P13)>=AE13/2,55+5*(AE13/2-SUM($E13:O13))/P13,IF(SUM($E13:Q13)>=AE13/2,60+5*(AE13/2-SUM($E13:P13))/Q13,IF(SUM($E13:R13)>=AE13/2,65+5*(AE13/2-SUM($E13:Q13))/R13,IF(SUM($E13:S13)>=AE13/2,70+5*(AE13/2-SUM($E13:R13))/S13,IF(SUM($E13:T13)>=AE13/2,75+5*(AE13/2-SUM($E13:S13))/T13,"")))))))))))))))) | AL13: =SUM(H13:Q13) | AM13: 0.076 | AN13: 0.099 | AO13: =IF(AND(ISNUMBER(AN13),ISNUMBER(AM13)),(AN13-AM13)*100,"") | AP13: =IF(ISNUMBER(AN13),AN13*AL13,"") | AQ13: =IF(ISNUMBER(AN13),AL13,0) | AR13: 0.78 | AS13: internet users | AT13: 18+ | AU13: 0.88 | AV13: =H13*0.4+I13+J13+K13+L13+M13+N13+O13+P13+Q13+R13+S13+T13+U13 | AX13: =IF(ISNUMBER(AW13),AW13,AR13*AU13*AV13) | AY13: =AX13/AV13 | AZ13: B | BA13: Yes | BB13: =IF(BA13="Yes",AX13,0) | BC13: =IF(AND(BA13="Yes",ISNUMBER(AP13)),AP13,0) | BD13: =IF(BA13="Yes",AX13,IF(ISNUMBER(AP13),AP13,0)) | BE13: Used neural networks (generative AI) at least once in the past year (share of internet users 18+) | BF13: 25-27 June 2026 (VTsIOM-Online, n=3,209) | BG13: VTsIOM (Russian Public Opinion Research Center, state-owned): Neural networks in our lives (analytical review) | BH13: https://wciom.ru/analytical-reviews/analiticheskii-obzor/neiroseti-v-nashei-zhizni
A14: ETH | B14: Ethiopia | C14: Sub-Saharan Africa | D14: Low income | E14: 19653558 | F14: 17491797 | G14: 15390336 | H14: 14814861 | I14: 13612857 | J14: 11656924 | K14: 9753096 | L14: 7718009 | M14: 5887608 | N14: 4976670 | O14: 4039200 | P14: 3374179 | Q14: 2638163 | R14: 1845988 | S14: 1223123 | T14: 801748 | U14: 593938 | V14: 67595952 | W14: 67876103 | X14: =SUM(E14:G14) | Y14: =SUM(H14:I14) | Z14: =SUM(J14:K14) | AA14: =SUM(L14:M14) | AB14: =SUM(N14:O14) | AC14: =SUM(P14:Q14) | AD14: =SUM(R14:U14) | AE14: =SUM(X14:AD14) | AF14: =AE14/SUM($AE$5:$AE$222) | AG14: =RANK(AE14,$AE$5:$AE$222) | AH14: 132059767 | AI14: =IF(AH14>0,AE14/AH14-1,"") | AJ14: 933 | AK14: =IF(SUM($E14:E14)>=AE14/2,0+5*(AE14/2-0)/E14,IF(SUM($E14:F14)>=AE14/2,5+5*(AE14/2-SUM($E14:E14))/F14,IF(SUM($E14:G14)>=AE14/2,10+5*(AE14/2-SUM($E14:F14))/G14,IF(SUM($E14:H14)>=AE14/2,15+5*(AE14/2-SUM($E14:G14))/H14,IF(SUM($E14:I14)>=AE14/2,20+5*(AE14/2-SUM($E14:H14))/I14,IF(SUM($E14:J14)>=AE14/2,25+5*(AE14/2-SUM($E14:I14))/J14,IF(SUM($E14:K14)>=AE14/2,30+5*(AE14/2-SUM($E14:J14))/K14,IF(SUM($E14:L14)>=AE14/2,35+5*(AE14/2-SUM($E14:K14))/L14,IF(SUM($E14:M14)>=AE14/2,40+5*(AE14/2-SUM($E14:L14))/M14,IF(SUM($E14:N14)>=AE14/2,45+5*(AE14/2-SUM($E14:M14))/N14,IF(SUM($E14:O14)>=AE14/2,50+5*(AE14/2-SUM($E14:N14))/O14,IF(SUM($E14:P14)>=AE14/2,55+5*(AE14/2-SUM($E14:O14))/P14,IF(SUM($E14:Q14)>=AE14/2,60+5*(AE14/2-SUM($E14:P14))/Q14,IF(SUM($E14:R14)>=AE14/2,65+5*(AE14/2-SUM($E14:Q14))/R14,IF(SUM($E14:S14)>=AE14/2,70+5*(AE14/2-SUM($E14:R14))/S14,IF(SUM($E14:T14)>=AE14/2,75+5*(AE14/2-SUM($E14:S14))/T14,"")))))))))))))))) | AL14: =SUM(H14:Q14) | AM14: 0.064 | AN14: 0.08 | AO14: =IF(AND(ISNUMBER(AN14),ISNUMBER(AM14)),(AN14-AM14)*100,"") | AP14: =IF(ISNUMBER(AN14),AN14*AL14,"") | AQ14: =IF(ISNUMBER(AN14),AL14,0) | BB14: =IF(BA14="Yes",AX14,0) | BC14: =IF(AND(BA14="Yes",ISNUMBER(AP14)),AP14,0) | BD14: =IF(BA14="Yes",AX14,IF(ISNUMBER(AP14),AP14,0))
A15: MEX | B15: Mexico | C15: Latin America & Caribbean | D15: Upper middle income | E15: 10122411 | F15: 10471455 | G15: 11193541 | H15: 11146497 | I15: 11100687 | J15: 10623243 | K15: 10396952 | L15: 9651333 | M15: 8773930 | N15: 8029534 | O15: 7425198 | P15: 6442687 | Q15: 5325664 | R15: 4116364 | S15: 2973258 | T15: 2018834 | U15: 2135313 | V15: 67964085 | W15: 63982816 | X15: =SUM(E15:G15) | Y15: =SUM(H15:I15) | Z15: =SUM(J15:K15) | AA15: =SUM(L15:M15) | AB15: =SUM(N15:O15) | AC15: =SUM(P15:Q15) | AD15: =SUM(R15:U15) | AE15: =SUM(X15:AD15) | AF15: =AE15/SUM($AE$5:$AE$222) | AG15: =RANK(AE15,$AE$5:$AE$222) | AH15: 130861007 | AI15: =IF(AH15>0,AE15/AH15-1,"") | AJ15: 13889 | AK15: =IF(SUM($E15:E15)>=AE15/2,0+5*(AE15/2-0)/E15,IF(SUM($E15:F15)>=AE15/2,5+5*(AE15/2-SUM($E15:E15))/F15,IF(SUM($E15:G15)>=AE15/2,10+5*(AE15/2-SUM($E15:F15))/G15,IF(SUM($E15:H15)>=AE15/2,15+5*(AE15/2-SUM($E15:G15))/H15,IF(SUM($E15:I15)>=AE15/2,20+5*(AE15/2-SUM($E15:H15))/I15,IF(SUM($E15:J15)>=AE15/2,25+5*(AE15/2-SUM($E15:I15))/J15,IF(SUM($E15:K15)>=AE15/2,30+5*(AE15/2-SUM($E15:J15))/K15,IF(SUM($E15:L15)>=AE15/2,35+5*(AE15/2-SUM($E15:K15))/L15,IF(SUM($E15:M15)>=AE15/2,40+5*(AE15/2-SUM($E15:L15))/M15,IF(SUM($E15:N15)>=AE15/2,45+5*(AE15/2-SUM($E15:M15))/N15,IF(SUM($E15:O15)>=AE15/2,50+5*(AE15/2-SUM($E15:N15))/O15,IF(SUM($E15:P15)>=AE15/2,55+5*(AE15/2-SUM($E15:O15))/P15,IF(SUM($E15:Q15)>=AE15/2,60+5*(AE15/2-SUM($E15:P15))/Q15,IF(SUM($E15:R15)>=AE15/2,65+5*(AE15/2-SUM($E15:Q15))/R15,IF(SUM($E15:S15)>=AE15/2,70+5*(AE15/2-SUM($E15:R15))/S15,IF(SUM($E15:T15)>=AE15/2,75+5*(AE15/2-SUM($E15:S15))/T15,"")))))))))))))))) | AL15: =SUM(H15:Q15) | AM15: 0.167 | AN15: 0.214 | AO15: =IF(AND(ISNUMBER(AN15),ISNUMBER(AM15)),(AN15-AM15)*100,"") | AP15: =IF(ISNUMBER(AN15),AN15*AL15,"") | AQ15: =IF(ISNUMBER(AN15),AL15,0) | BB15: =IF(BA15="Yes",AX15,0) | BC15: =IF(AND(BA15="Yes",ISNUMBER(AP15)),AP15,0) | BD15: =IF(BA15="Yes",AX15,IF(ISNUMBER(AP15),AP15,0))
A16: JPN | B16: Japan | C16: East Asia & Pacific | D16: High income | E16: 3928343 | F16: 4664779 | G16: 5271322 | H16: 5670299 | I16: 6141006 | J16: 6123015 | K16: 6060315 | L16: 6502393 | M16: 7306149 | N16: 8484888 | O16: 9944050 | P16: 8543519 | Q16: 7723916 | R16: 7276966 | S16: 7850400 | T16: 8711591 | U16: 13163780 | V16: 63215258 | W16: 60151473 | X16: =SUM(E16:G16) | Y16: =SUM(H16:I16) | Z16: =SUM(J16:K16) | AA16: =SUM(L16:M16) | AB16: =SUM(N16:O16) | AC16: =SUM(P16:Q16) | AD16: =SUM(R16:U16) | AE16: =SUM(X16:AD16) | AF16: =AE16/SUM($AE$5:$AE$222) | AG16: =RANK(AE16,$AE$5:$AE$222) | AH16: 123975371 | AI16: =IF(AH16>0,AE16/AH16-1,"") | AJ16: 35951 | AK16: =IF(SUM($E16:E16)>=AE16/2,0+5*(AE16/2-0)/E16,IF(SUM($E16:F16)>=AE16/2,5+5*(AE16/2-SUM($E16:E16))/F16,IF(SUM($E16:G16)>=AE16/2,10+5*(AE16/2-SUM($E16:F16))/G16,IF(SUM($E16:H16)>=AE16/2,15+5*(AE16/2-SUM($E16:G16))/H16,IF(SUM($E16:I16)>=AE16/2,20+5*(AE16/2-SUM($E16:H16))/I16,IF(SUM($E16:J16)>=AE16/2,25+5*(AE16/2-SUM($E16:I16))/J16,IF(SUM($E16:K16)>=AE16/2,30+5*(AE16/2-SUM($E16:J16))/K16,IF(SUM($E16:L16)>=AE16/2,35+5*(AE16/2-SUM($E16:K16))/L16,IF(SUM($E16:M16)>=AE16/2,40+5*(AE16/2-SUM($E16:L16))/M16,IF(SUM($E16:N16)>=AE16/2,45+5*(AE16/2-SUM($E16:M16))/N16,IF(SUM($E16:O16)>=AE16/2,50+5*(AE16/2-SUM($E16:N16))/O16,IF(SUM($E16:P16)>=AE16/2,55+5*(AE16/2-SUM($E16:O16))/P16,IF(SUM($E16:Q16)>=AE16/2,60+5*(AE16/2-SUM($E16:P16))/Q16,IF(SUM($E16:R16)>=AE16/2,65+5*(AE16/2-SUM($E16:Q16))/R16,IF(SUM($E16:S16)>=AE16/2,70+5*(AE16/2-SUM($E16:R16))/S16,IF(SUM($E16:T16)>=AE16/2,75+5*(AE16/2-SUM($E16:S16))/T16,"")))))))))))))))) | AL16: =SUM(H16:Q16) | AM16: 0.167 | AN16: 0.247 | AO16: =IF(AND(ISNUMBER(AN16),ISNUMBER(AM16)),(AN16-AM16)*100,"") | AP16: =IF(ISNUMBER(AN16),AN16*AL16,"") | AQ16: =IF(ISNUMBER(AN16),AL16,0) | AR16: 0.588 | AS16: population | AT16: 15-69 | AU16: 1 | AV16: =H16+I16+J16+K16+L16+M16+N16+O16+P16+Q16+R16 | AX16: =IF(ISNUMBER(AW16),AW16,AR16*AU16*AV16) | AY16: =AX16/AV16 | AZ16: A | BA16: Yes | BB16: =IF(BA16="Yes",AX16,0) | BC16: =IF(AND(BA16="Yes",ISNUMBER(AP16)),AP16,0) | BD16: =IF(BA16="Yes",AX16,IF(ISNUMBER(AP16),AP16,0)) | BE16: Have ever used at least one generative AI service, for work or daily life | BF16: January-February 2026 (online panel, n=1,236) | BG16: Ministry of Internal Affairs and Communications (MIC): White Paper on Information and Communications 2026 (Reiwa 8), Part I ch. 1 | BH16: https://www.soumu.go.jp/johotsusintokei/whitepaper/ja/r08/text/nd111110.txt
